2022-02-13 01:27:13,451:INFO:PyCaret Supervised Module
2022-02-13 01:27:13,451:INFO:ML Usecase: classification
2022-02-13 01:27:13,452:INFO:version 2.3.6
2022-02-13 01:27:13,452:INFO:Initializing setup()
2022-02-13 01:27:13,452:INFO:setup(target=profit, ml_usecase=classification, available_plots={'parameter': 'Hyperparameters', 'auc': 'AUC', 'confusion_matrix': 'Confusion Matrix', 'threshold': 'Threshold', 'pr': 'Precision Recall', 'error': 'Prediction Error', 'class_report': 'Class Report', 'rfe': 'Feature Selection', 'learning': 'Learning Curve', 'manifold': 'Manifold Learning', 'calibration': 'Calibration Curve', 'vc': 'Validation Curve', 'dimension': 'Dimensions', 'feature': 'Feature Importance', 'feature_all': 'Feature Importance (All)', 'boundary': 'Decision Boundary', 'lift': 'Lift Chart', 'gain': 'Gain Chart', 'tree': 'Decision Tree', 'ks': 'KS Statistic Plot'}, train_size=0.7, test_data=None, preprocess=True, imputation_type=simple, iterative_imputation_iters=5, categorical_features=None, categorical_imputation=constant, categorical_iterative_imputer=lightgbm, ordinal_features=None, high_cardinality_features=None, high_cardinality_method=frequency, numeric_features=None, numeric_imputation=mean, numeric_iterative_imputer=lightgbm, date_features=None, ignore_features=None, normalize=False, normalize_method=zscore, transformation=False, transformation_method=yeo-johnson, handle_unknown_categorical=True, unknown_categorical_method=least_frequent, pca=False, pca_method=linear, pca_components=None, ignore_low_variance=False, combine_rare_levels=False, rare_level_threshold=0.1, bin_numeric_features=None, remove_outliers=False, outliers_threshold=0.05, remove_multicollinearity=False, multicollinearity_threshold=0.9, remove_perfect_collinearity=True, create_clusters=False, cluster_iter=20, polynomial_features=False, polynomial_degree=2, trigonometry_features=False, polynomial_threshold=0.1, group_features=None, group_names=None, feature_selection=False, feature_selection_threshold=0.8, feature_selection_method=classic, feature_interaction=False, feature_ratio=False, interaction_threshold=0.01, fix_imbalance=False, fix_imbalance_method=None, transform_target=False, transform_target_method=box-cox, data_split_shuffle=True, data_split_stratify=False, fold_strategy=stratifiedkfold, fold=10, fold_shuffle=False, fold_groups=None, n_jobs=-1, use_gpu=False, custom_pipeline=None, html=True, session_id=None, log_experiment=False, experiment_name=None, log_plots=False, log_profile=False, log_data=False, silent=True, verbose=False, profile=False, profile_kwargs=None, display=None)
2022-02-13 01:27:13,465:INFO:Checking environment
2022-02-13 01:27:13,465:INFO:python_version: 3.8.5
2022-02-13 01:27:13,466:INFO:python_build: ('default', 'Sep  3 2020 21:29:08')
2022-02-13 01:27:13,466:INFO:machine: AMD64
2022-02-13 01:27:13,467:INFO:platform: Windows-10-10.0.19041-SP0
2022-02-13 01:27:13,467:INFO:Memory: svmem(total=17033728000, available=7812505600, percent=54.1, used=9221222400, free=7812505600)
2022-02-13 01:27:13,467:INFO:Physical Core: 4
2022-02-13 01:27:13,467:INFO:Logical Core: 8
2022-02-13 01:27:13,468:INFO:Checking libraries
2022-02-13 01:27:13,468:INFO:pd==1.1.3
2022-02-13 01:27:13,468:INFO:numpy==1.19.2
2022-02-13 01:27:13,468:INFO:sklearn==0.23.2
2022-02-13 01:27:13,469:INFO:lightgbm==3.3.2
2022-02-13 01:27:13,577:INFO:catboost==1.0.0
2022-02-13 01:27:13,579:WARNING:xgboost not found
2022-02-13 01:27:14,258:INFO:mlflow==1.23.1
2022-02-13 01:27:14,259:INFO:Checking Exceptions
2022-02-13 01:27:14,259:INFO:Declaring global variables
2022-02-13 01:27:14,259:INFO:USI: 74f5
2022-02-13 01:27:14,259:INFO:pycaret_globals: {'seed', 'gpu_param', '_available_plots', 'y_train', 'master_model_container', 'fix_imbalance_method_param', 'experiment__', 'log_plots_param', 'data_before_preprocess', 'X_test', 'fold_generator', 'imputation_regressor', 'fold_param', 'exp_name_log', 'fold_groups_param', 'y', 'target_param', 'transform_target_method_param', 'imputation_classifier', '_all_metrics', 'USI', 'stratify_param', 'iterative_imputation_iters_param', 'display_container', 'pycaret_globals', 'n_jobs_param', '_gpu_n_jobs_param', 'create_model_container', '_ml_usecase', 'X', 'fold_groups_param_full', 'fix_imbalance_param', 'prep_pipe', 'y_test', '_internal_pipeline', '_all_models', '_all_models_internal', 'html_param', 'X_train', 'transform_target_param', 'fold_shuffle_param', 'logging_param'}
2022-02-13 01:27:14,259:INFO:Preparing display monitor
2022-02-13 01:27:14,259:INFO:Importing libraries
2022-02-13 01:27:14,259:INFO:Copying data for preprocessing
2022-02-13 01:27:14,261:INFO:Declaring preprocessing parameters
2022-02-13 01:27:14,268:INFO:Creating preprocessing pipeline
2022-02-13 01:27:14,281:INFO:Preprocessing pipeline created successfully
2022-02-13 01:27:14,281:ERROR:(Process Exit): setup has been interupted with user command 'quit'. setup must rerun.
2022-02-13 01:27:14,281:INFO:Creating global containers
2022-02-13 01:27:14,283:INFO:Internal pipeline: Pipeline(memory=None, steps=[('empty_step', 'passthrough')], verbose=False)
2022-02-13 01:27:15,031:WARNING:Couldn't import xgboost.XGBClassifier
2022-02-13 01:27:15,120:WARNING:Couldn't import xgboost.XGBClassifier
2022-02-13 01:27:15,120:INFO:Creating grid variables
2022-02-13 01:27:15,138:INFO:create_model_container: 0
2022-02-13 01:27:15,139:INFO:master_model_container: 0
2022-02-13 01:27:15,139:INFO:display_container: 1
2022-02-13 01:27:15,144:INFO:Pipeline(memory=None,
         steps=[('dtypes',
                 DataTypes_Auto_infer(categorical_features=[],
                                      display_types=False, features_todrop=[],
                                      id_columns=[],
                                      ml_usecase='classification',
                                      numerical_features=[], target='profit',
                                      time_features=[])),
                ('imputer',
                 Simple_Imputer(categorical_strategy='not_available',
                                fill_value_categorical=None,
                                fill_value_numerical=None,
                                numeric_stra...
                ('scaling', 'passthrough'), ('P_transform', 'passthrough'),
                ('binn', 'passthrough'), ('rem_outliers', 'passthrough'),
                ('cluster_all', 'passthrough'),
                ('dummy', Dummify(target='profit')),
                ('fix_perfect', Remove_100(target='profit')),
                ('clean_names', Clean_Colum_Names()),
                ('feature_select', 'passthrough'), ('fix_multi', 'passthrough'),
                ('dfs', 'passthrough'), ('pca', 'passthrough')],
         verbose=False)
2022-02-13 01:27:15,144:INFO:setup() succesfully completed......................................
2022-02-13 01:27:15,274:INFO:Initializing compare_models()
2022-02-13 01:27:15,274:INFO:compare_models(include=None, fold=None, round=4, cross_validation=True, sort=Accuracy, n_select=3, budget_time=None, turbo=True, errors=ignore, fit_kwargs=None, groups=None, probability_threshold=None, verbose=True, display=None, exclude=None)
2022-02-13 01:27:15,274:INFO:Checking exceptions
2022-02-13 01:27:15,275:INFO:Preparing display monitor
2022-02-13 01:27:15,275:INFO:Preparing display monitor
2022-02-13 01:27:15,304:INFO:Initializing Logistic Regression
2022-02-13 01:27:15,304:INFO:Total runtime is 0.0 minutes
2022-02-13 01:27:15,312:INFO:SubProcess create_model() called ==================================
2022-02-13 01:27:15,312:INFO:Initializing create_model()
2022-02-13 01:27:15,313:INFO:create_model(estimator=lr, fold=StratifiedKFold(n_splits=10, random_state=None, shuffle=False), round=4, cross_validation=True, predict=True, fit_kwargs={}, groups=None, refit=False, verbose=False, system=False, metrics=None, add_to_model_list=True, probability_threshold=None, display=<pycaret.internal.Display.Display object at 0x000001CFB6416DF0>, kwargs={})
2022-02-13 01:27:15,313:INFO:Checking exceptions
2022-02-13 01:27:15,313:INFO:Importing libraries
2022-02-13 01:27:15,313:INFO:Copying training dataset
2022-02-13 01:27:15,316:INFO:Defining folds
2022-02-13 01:27:15,316:INFO:Declaring metric variables
2022-02-13 01:27:15,323:INFO:Importing untrained model
2022-02-13 01:27:15,335:INFO:Logistic Regression Imported succesfully
2022-02-13 01:27:15,355:INFO:Starting cross validation
2022-02-13 01:27:15,356:INFO:Cross validating with StratifiedKFold(n_splits=10, random_state=None, shuffle=False), n_jobs=-1
2022-02-13 01:27:15,363:WARNING:create_model() for lr raised an exception or returned all 0.0, trying without fit_kwargs:
2022-02-13 01:27:15,387:WARNING:Traceback (most recent call last):
  File "C:\Users\TP\anaconda3\lib\site-packages\joblib\parallel.py", line 827, in dispatch_one_batch
    tasks = self._ready_batches.get(block=False)
  File "C:\Users\TP\anaconda3\lib\queue.py", line 167, in get
    raise Empty
_queue.Empty

During handling of the above exception, another exception occurred:

Traceback (most recent call last):
  File "C:\Users\TP\AppData\Roaming\Python\Python38\site-packages\pycaret\internal\tabular.py", line 2206, in compare_models
    model, model_fit_time = create_model_supervised(**create_model_args)
  File "C:\Users\TP\AppData\Roaming\Python\Python38\site-packages\pycaret\internal\tabular.py", line 3171, in create_model_supervised
    scores = cross_validate(
  File "C:\Users\TP\anaconda3\lib\site-packages\sklearn\utils\validation.py", line 72, in inner_f
    return f(**kwargs)
  File "C:\Users\TP\anaconda3\lib\site-packages\sklearn\model_selection\_validation.py", line 242, in cross_validate
    scores = parallel(
  File "C:\Users\TP\anaconda3\lib\site-packages\joblib\parallel.py", line 1048, in __call__
    if self.dispatch_one_batch(iterator):
  File "C:\Users\TP\anaconda3\lib\site-packages\joblib\parallel.py", line 838, in dispatch_one_batch
    islice = list(itertools.islice(iterator, big_batch_size))
  File "C:\Users\TP\anaconda3\lib\site-packages\sklearn\model_selection\_validation.py", line 242, in <genexpr>
    scores = parallel(
  File "C:\Users\TP\anaconda3\lib\site-packages\sklearn\model_selection\_split.py", line 336, in split
    for train, test in super().split(X, y, groups):
  File "C:\Users\TP\anaconda3\lib\site-packages\sklearn\model_selection\_split.py", line 80, in split
    for test_index in self._iter_test_masks(X, y, groups):
  File "C:\Users\TP\anaconda3\lib\site-packages\sklearn\model_selection\_split.py", line 697, in _iter_test_masks
    test_folds = self._make_test_folds(X, y)
  File "C:\Users\TP\anaconda3\lib\site-packages\sklearn\model_selection\_split.py", line 649, in _make_test_folds
    raise ValueError(
ValueError: Supported target types are: ('binary', 'multiclass'). Got 'continuous' instead.

2022-02-13 01:27:15,387:INFO:Initializing create_model()
2022-02-13 01:27:15,387:INFO:create_model(estimator=lr, fold=StratifiedKFold(n_splits=10, random_state=None, shuffle=False), round=4, cross_validation=True, predict=True, fit_kwargs={}, groups=None, refit=False, verbose=False, system=False, metrics=None, add_to_model_list=True, probability_threshold=None, display=<pycaret.internal.Display.Display object at 0x000001CFB6416DF0>, kwargs={})
2022-02-13 01:27:15,387:INFO:Checking exceptions
2022-02-13 01:27:15,387:INFO:Importing libraries
2022-02-13 01:27:15,387:INFO:Copying training dataset
2022-02-13 01:27:15,389:INFO:Defining folds
2022-02-13 01:27:15,390:INFO:Declaring metric variables
2022-02-13 01:27:15,401:INFO:Importing untrained model
2022-02-13 01:27:15,415:INFO:Logistic Regression Imported succesfully
2022-02-13 01:27:15,444:INFO:Starting cross validation
2022-02-13 01:27:15,445:INFO:Cross validating with StratifiedKFold(n_splits=10, random_state=None, shuffle=False), n_jobs=-1
2022-02-13 01:27:15,448:ERROR:create_model() for lr raised an exception or returned all 0.0:
2022-02-13 01:27:15,451:ERROR:Traceback (most recent call last):
  File "C:\Users\TP\anaconda3\lib\site-packages\joblib\parallel.py", line 827, in dispatch_one_batch
    tasks = self._ready_batches.get(block=False)
  File "C:\Users\TP\anaconda3\lib\queue.py", line 167, in get
    raise Empty
_queue.Empty

During handling of the above exception, another exception occurred:

Traceback (most recent call last):
  File "C:\Users\TP\AppData\Roaming\Python\Python38\site-packages\pycaret\internal\tabular.py", line 2206, in compare_models
    model, model_fit_time = create_model_supervised(**create_model_args)
  File "C:\Users\TP\AppData\Roaming\Python\Python38\site-packages\pycaret\internal\tabular.py", line 3171, in create_model_supervised
    scores = cross_validate(
  File "C:\Users\TP\anaconda3\lib\site-packages\sklearn\utils\validation.py", line 72, in inner_f
    return f(**kwargs)
  File "C:\Users\TP\anaconda3\lib\site-packages\sklearn\model_selection\_validation.py", line 242, in cross_validate
    scores = parallel(
  File "C:\Users\TP\anaconda3\lib\site-packages\joblib\parallel.py", line 1048, in __call__
    if self.dispatch_one_batch(iterator):
  File "C:\Users\TP\anaconda3\lib\site-packages\joblib\parallel.py", line 838, in dispatch_one_batch
    islice = list(itertools.islice(iterator, big_batch_size))
  File "C:\Users\TP\anaconda3\lib\site-packages\sklearn\model_selection\_validation.py", line 242, in <genexpr>
    scores = parallel(
  File "C:\Users\TP\anaconda3\lib\site-packages\sklearn\model_selection\_split.py", line 336, in split
    for train, test in super().split(X, y, groups):
  File "C:\Users\TP\anaconda3\lib\site-packages\sklearn\model_selection\_split.py", line 80, in split
    for test_index in self._iter_test_masks(X, y, groups):
  File "C:\Users\TP\anaconda3\lib\site-packages\sklearn\model_selection\_split.py", line 697, in _iter_test_masks
    test_folds = self._make_test_folds(X, y)
  File "C:\Users\TP\anaconda3\lib\site-packages\sklearn\model_selection\_split.py", line 649, in _make_test_folds
    raise ValueError(
ValueError: Supported target types are: ('binary', 'multiclass'). Got 'continuous' instead.

During handling of the above exception, another exception occurred:

Traceback (most recent call last):
  File "C:\Users\TP\anaconda3\lib\site-packages\joblib\parallel.py", line 827, in dispatch_one_batch
    tasks = self._ready_batches.get(block=False)
  File "C:\Users\TP\anaconda3\lib\queue.py", line 167, in get
    raise Empty
_queue.Empty

During handling of the above exception, another exception occurred:

Traceback (most recent call last):
  File "C:\Users\TP\AppData\Roaming\Python\Python38\site-packages\pycaret\internal\tabular.py", line 2215, in compare_models
    model, model_fit_time = create_model_supervised(**create_model_args)
  File "C:\Users\TP\AppData\Roaming\Python\Python38\site-packages\pycaret\internal\tabular.py", line 3171, in create_model_supervised
    scores = cross_validate(
  File "C:\Users\TP\anaconda3\lib\site-packages\sklearn\utils\validation.py", line 72, in inner_f
    return f(**kwargs)
  File "C:\Users\TP\anaconda3\lib\site-packages\sklearn\model_selection\_validation.py", line 242, in cross_validate
    scores = parallel(
  File "C:\Users\TP\anaconda3\lib\site-packages\joblib\parallel.py", line 1048, in __call__
    if self.dispatch_one_batch(iterator):
  File "C:\Users\TP\anaconda3\lib\site-packages\joblib\parallel.py", line 838, in dispatch_one_batch
    islice = list(itertools.islice(iterator, big_batch_size))
  File "C:\Users\TP\anaconda3\lib\site-packages\sklearn\model_selection\_validation.py", line 242, in <genexpr>
    scores = parallel(
  File "C:\Users\TP\anaconda3\lib\site-packages\sklearn\model_selection\_split.py", line 336, in split
    for train, test in super().split(X, y, groups):
  File "C:\Users\TP\anaconda3\lib\site-packages\sklearn\model_selection\_split.py", line 80, in split
    for test_index in self._iter_test_masks(X, y, groups):
  File "C:\Users\TP\anaconda3\lib\site-packages\sklearn\model_selection\_split.py", line 697, in _iter_test_masks
    test_folds = self._make_test_folds(X, y)
  File "C:\Users\TP\anaconda3\lib\site-packages\sklearn\model_selection\_split.py", line 649, in _make_test_folds
    raise ValueError(
ValueError: Supported target types are: ('binary', 'multiclass'). Got 'continuous' instead.

2022-02-13 01:27:15,452:INFO:Initializing K Neighbors Classifier
2022-02-13 01:27:15,452:INFO:Total runtime is 0.0024767279624938964 minutes
2022-02-13 01:27:15,466:INFO:SubProcess create_model() called ==================================
2022-02-13 01:27:15,467:INFO:Initializing create_model()
2022-02-13 01:27:15,467:INFO:create_model(estimator=knn, fold=StratifiedKFold(n_splits=10, random_state=None, shuffle=False), round=4, cross_validation=True, predict=True, fit_kwargs={}, groups=None, refit=False, verbose=False, system=False, metrics=None, add_to_model_list=True, probability_threshold=None, display=<pycaret.internal.Display.Display object at 0x000001CFB6416DF0>, kwargs={})
2022-02-13 01:27:15,467:INFO:Checking exceptions
2022-02-13 01:27:15,467:INFO:Importing libraries
2022-02-13 01:27:15,467:INFO:Copying training dataset
2022-02-13 01:27:15,469:INFO:Defining folds
2022-02-13 01:27:15,470:INFO:Declaring metric variables
2022-02-13 01:27:15,486:INFO:Importing untrained model
2022-02-13 01:27:15,499:INFO:K Neighbors Classifier Imported succesfully
2022-02-13 01:27:15,541:INFO:Starting cross validation
2022-02-13 01:27:15,542:INFO:Cross validating with StratifiedKFold(n_splits=10, random_state=None, shuffle=False), n_jobs=-1
2022-02-13 01:27:15,544:WARNING:create_model() for knn raised an exception or returned all 0.0, trying without fit_kwargs:
2022-02-13 01:27:15,546:WARNING:Traceback (most recent call last):
  File "C:\Users\TP\anaconda3\lib\site-packages\joblib\parallel.py", line 827, in dispatch_one_batch
    tasks = self._ready_batches.get(block=False)
  File "C:\Users\TP\anaconda3\lib\queue.py", line 167, in get
    raise Empty
_queue.Empty

During handling of the above exception, another exception occurred:

Traceback (most recent call last):
  File "C:\Users\TP\AppData\Roaming\Python\Python38\site-packages\pycaret\internal\tabular.py", line 2206, in compare_models
    model, model_fit_time = create_model_supervised(**create_model_args)
  File "C:\Users\TP\AppData\Roaming\Python\Python38\site-packages\pycaret\internal\tabular.py", line 3171, in create_model_supervised
    scores = cross_validate(
  File "C:\Users\TP\anaconda3\lib\site-packages\sklearn\utils\validation.py", line 72, in inner_f
    return f(**kwargs)
  File "C:\Users\TP\anaconda3\lib\site-packages\sklearn\model_selection\_validation.py", line 242, in cross_validate
    scores = parallel(
  File "C:\Users\TP\anaconda3\lib\site-packages\joblib\parallel.py", line 1048, in __call__
    if self.dispatch_one_batch(iterator):
  File "C:\Users\TP\anaconda3\lib\site-packages\joblib\parallel.py", line 838, in dispatch_one_batch
    islice = list(itertools.islice(iterator, big_batch_size))
  File "C:\Users\TP\anaconda3\lib\site-packages\sklearn\model_selection\_validation.py", line 242, in <genexpr>
    scores = parallel(
  File "C:\Users\TP\anaconda3\lib\site-packages\sklearn\model_selection\_split.py", line 336, in split
    for train, test in super().split(X, y, groups):
  File "C:\Users\TP\anaconda3\lib\site-packages\sklearn\model_selection\_split.py", line 80, in split
    for test_index in self._iter_test_masks(X, y, groups):
  File "C:\Users\TP\anaconda3\lib\site-packages\sklearn\model_selection\_split.py", line 697, in _iter_test_masks
    test_folds = self._make_test_folds(X, y)
  File "C:\Users\TP\anaconda3\lib\site-packages\sklearn\model_selection\_split.py", line 649, in _make_test_folds
    raise ValueError(
ValueError: Supported target types are: ('binary', 'multiclass'). Got 'continuous' instead.

2022-02-13 01:27:15,547:INFO:Initializing create_model()
2022-02-13 01:27:15,547:INFO:create_model(estimator=knn, fold=StratifiedKFold(n_splits=10, random_state=None, shuffle=False), round=4, cross_validation=True, predict=True, fit_kwargs={}, groups=None, refit=False, verbose=False, system=False, metrics=None, add_to_model_list=True, probability_threshold=None, display=<pycaret.internal.Display.Display object at 0x000001CFB6416DF0>, kwargs={})
2022-02-13 01:27:15,547:INFO:Checking exceptions
2022-02-13 01:27:15,547:INFO:Importing libraries
2022-02-13 01:27:15,548:INFO:Copying training dataset
2022-02-13 01:27:15,550:INFO:Defining folds
2022-02-13 01:27:15,550:INFO:Declaring metric variables
2022-02-13 01:27:15,562:INFO:Importing untrained model
2022-02-13 01:27:15,576:INFO:K Neighbors Classifier Imported succesfully
2022-02-13 01:27:15,598:INFO:Starting cross validation
2022-02-13 01:27:15,599:INFO:Cross validating with StratifiedKFold(n_splits=10, random_state=None, shuffle=False), n_jobs=-1
2022-02-13 01:27:15,601:ERROR:create_model() for knn raised an exception or returned all 0.0:
2022-02-13 01:27:15,604:ERROR:Traceback (most recent call last):
  File "C:\Users\TP\anaconda3\lib\site-packages\joblib\parallel.py", line 827, in dispatch_one_batch
    tasks = self._ready_batches.get(block=False)
  File "C:\Users\TP\anaconda3\lib\queue.py", line 167, in get
    raise Empty
_queue.Empty

During handling of the above exception, another exception occurred:

Traceback (most recent call last):
  File "C:\Users\TP\AppData\Roaming\Python\Python38\site-packages\pycaret\internal\tabular.py", line 2206, in compare_models
    model, model_fit_time = create_model_supervised(**create_model_args)
  File "C:\Users\TP\AppData\Roaming\Python\Python38\site-packages\pycaret\internal\tabular.py", line 3171, in create_model_supervised
    scores = cross_validate(
  File "C:\Users\TP\anaconda3\lib\site-packages\sklearn\utils\validation.py", line 72, in inner_f
    return f(**kwargs)
  File "C:\Users\TP\anaconda3\lib\site-packages\sklearn\model_selection\_validation.py", line 242, in cross_validate
    scores = parallel(
  File "C:\Users\TP\anaconda3\lib\site-packages\joblib\parallel.py", line 1048, in __call__
    if self.dispatch_one_batch(iterator):
  File "C:\Users\TP\anaconda3\lib\site-packages\joblib\parallel.py", line 838, in dispatch_one_batch
    islice = list(itertools.islice(iterator, big_batch_size))
  File "C:\Users\TP\anaconda3\lib\site-packages\sklearn\model_selection\_validation.py", line 242, in <genexpr>
    scores = parallel(
  File "C:\Users\TP\anaconda3\lib\site-packages\sklearn\model_selection\_split.py", line 336, in split
    for train, test in super().split(X, y, groups):
  File "C:\Users\TP\anaconda3\lib\site-packages\sklearn\model_selection\_split.py", line 80, in split
    for test_index in self._iter_test_masks(X, y, groups):
  File "C:\Users\TP\anaconda3\lib\site-packages\sklearn\model_selection\_split.py", line 697, in _iter_test_masks
    test_folds = self._make_test_folds(X, y)
  File "C:\Users\TP\anaconda3\lib\site-packages\sklearn\model_selection\_split.py", line 649, in _make_test_folds
    raise ValueError(
ValueError: Supported target types are: ('binary', 'multiclass'). Got 'continuous' instead.

During handling of the above exception, another exception occurred:

Traceback (most recent call last):
  File "C:\Users\TP\anaconda3\lib\site-packages\joblib\parallel.py", line 827, in dispatch_one_batch
    tasks = self._ready_batches.get(block=False)
  File "C:\Users\TP\anaconda3\lib\queue.py", line 167, in get
    raise Empty
_queue.Empty

During handling of the above exception, another exception occurred:

Traceback (most recent call last):
  File "C:\Users\TP\AppData\Roaming\Python\Python38\site-packages\pycaret\internal\tabular.py", line 2215, in compare_models
    model, model_fit_time = create_model_supervised(**create_model_args)
  File "C:\Users\TP\AppData\Roaming\Python\Python38\site-packages\pycaret\internal\tabular.py", line 3171, in create_model_supervised
    scores = cross_validate(
  File "C:\Users\TP\anaconda3\lib\site-packages\sklearn\utils\validation.py", line 72, in inner_f
    return f(**kwargs)
  File "C:\Users\TP\anaconda3\lib\site-packages\sklearn\model_selection\_validation.py", line 242, in cross_validate
    scores = parallel(
  File "C:\Users\TP\anaconda3\lib\site-packages\joblib\parallel.py", line 1048, in __call__
    if self.dispatch_one_batch(iterator):
  File "C:\Users\TP\anaconda3\lib\site-packages\joblib\parallel.py", line 838, in dispatch_one_batch
    islice = list(itertools.islice(iterator, big_batch_size))
  File "C:\Users\TP\anaconda3\lib\site-packages\sklearn\model_selection\_validation.py", line 242, in <genexpr>
    scores = parallel(
  File "C:\Users\TP\anaconda3\lib\site-packages\sklearn\model_selection\_split.py", line 336, in split
    for train, test in super().split(X, y, groups):
  File "C:\Users\TP\anaconda3\lib\site-packages\sklearn\model_selection\_split.py", line 80, in split
    for test_index in self._iter_test_masks(X, y, groups):
  File "C:\Users\TP\anaconda3\lib\site-packages\sklearn\model_selection\_split.py", line 697, in _iter_test_masks
    test_folds = self._make_test_folds(X, y)
  File "C:\Users\TP\anaconda3\lib\site-packages\sklearn\model_selection\_split.py", line 649, in _make_test_folds
    raise ValueError(
ValueError: Supported target types are: ('binary', 'multiclass'). Got 'continuous' instead.

2022-02-13 01:27:15,605:INFO:Initializing Naive Bayes
2022-02-13 01:27:15,605:INFO:Total runtime is 0.005019915103912353 minutes
2022-02-13 01:27:15,617:INFO:SubProcess create_model() called ==================================
2022-02-13 01:27:15,617:INFO:Initializing create_model()
2022-02-13 01:27:15,617:INFO:create_model(estimator=nb, fold=StratifiedKFold(n_splits=10, random_state=None, shuffle=False), round=4, cross_validation=True, predict=True, fit_kwargs={}, groups=None, refit=False, verbose=False, system=False, metrics=None, add_to_model_list=True, probability_threshold=None, display=<pycaret.internal.Display.Display object at 0x000001CFB6416DF0>, kwargs={})
2022-02-13 01:27:15,617:INFO:Checking exceptions
2022-02-13 01:27:15,618:INFO:Importing libraries
2022-02-13 01:27:15,618:INFO:Copying training dataset
2022-02-13 01:27:15,624:INFO:Defining folds
2022-02-13 01:27:15,624:INFO:Declaring metric variables
2022-02-13 01:27:15,635:INFO:Importing untrained model
2022-02-13 01:27:15,647:INFO:Naive Bayes Imported succesfully
2022-02-13 01:27:15,671:INFO:Starting cross validation
2022-02-13 01:27:15,671:INFO:Cross validating with StratifiedKFold(n_splits=10, random_state=None, shuffle=False), n_jobs=-1
2022-02-13 01:27:15,673:WARNING:create_model() for nb raised an exception or returned all 0.0, trying without fit_kwargs:
2022-02-13 01:27:15,675:WARNING:Traceback (most recent call last):
  File "C:\Users\TP\anaconda3\lib\site-packages\joblib\parallel.py", line 827, in dispatch_one_batch
    tasks = self._ready_batches.get(block=False)
  File "C:\Users\TP\anaconda3\lib\queue.py", line 167, in get
    raise Empty
_queue.Empty

During handling of the above exception, another exception occurred:

Traceback (most recent call last):
  File "C:\Users\TP\AppData\Roaming\Python\Python38\site-packages\pycaret\internal\tabular.py", line 2206, in compare_models
    model, model_fit_time = create_model_supervised(**create_model_args)
  File "C:\Users\TP\AppData\Roaming\Python\Python38\site-packages\pycaret\internal\tabular.py", line 3171, in create_model_supervised
    scores = cross_validate(
  File "C:\Users\TP\anaconda3\lib\site-packages\sklearn\utils\validation.py", line 72, in inner_f
    return f(**kwargs)
  File "C:\Users\TP\anaconda3\lib\site-packages\sklearn\model_selection\_validation.py", line 242, in cross_validate
    scores = parallel(
  File "C:\Users\TP\anaconda3\lib\site-packages\joblib\parallel.py", line 1048, in __call__
    if self.dispatch_one_batch(iterator):
  File "C:\Users\TP\anaconda3\lib\site-packages\joblib\parallel.py", line 838, in dispatch_one_batch
    islice = list(itertools.islice(iterator, big_batch_size))
  File "C:\Users\TP\anaconda3\lib\site-packages\sklearn\model_selection\_validation.py", line 242, in <genexpr>
    scores = parallel(
  File "C:\Users\TP\anaconda3\lib\site-packages\sklearn\model_selection\_split.py", line 336, in split
    for train, test in super().split(X, y, groups):
  File "C:\Users\TP\anaconda3\lib\site-packages\sklearn\model_selection\_split.py", line 80, in split
    for test_index in self._iter_test_masks(X, y, groups):
  File "C:\Users\TP\anaconda3\lib\site-packages\sklearn\model_selection\_split.py", line 697, in _iter_test_masks
    test_folds = self._make_test_folds(X, y)
  File "C:\Users\TP\anaconda3\lib\site-packages\sklearn\model_selection\_split.py", line 649, in _make_test_folds
    raise ValueError(
ValueError: Supported target types are: ('binary', 'multiclass'). Got 'continuous' instead.

2022-02-13 01:27:15,675:INFO:Initializing create_model()
2022-02-13 01:27:15,675:INFO:create_model(estimator=nb, fold=StratifiedKFold(n_splits=10, random_state=None, shuffle=False), round=4, cross_validation=True, predict=True, fit_kwargs={}, groups=None, refit=False, verbose=False, system=False, metrics=None, add_to_model_list=True, probability_threshold=None, display=<pycaret.internal.Display.Display object at 0x000001CFB6416DF0>, kwargs={})
2022-02-13 01:27:15,675:INFO:Checking exceptions
2022-02-13 01:27:15,675:INFO:Importing libraries
2022-02-13 01:27:15,675:INFO:Copying training dataset
2022-02-13 01:27:15,678:INFO:Defining folds
2022-02-13 01:27:15,678:INFO:Declaring metric variables
2022-02-13 01:27:15,688:INFO:Importing untrained model
2022-02-13 01:27:15,699:INFO:Naive Bayes Imported succesfully
2022-02-13 01:27:15,718:INFO:Starting cross validation
2022-02-13 01:27:15,719:INFO:Cross validating with StratifiedKFold(n_splits=10, random_state=None, shuffle=False), n_jobs=-1
2022-02-13 01:27:15,720:ERROR:create_model() for nb raised an exception or returned all 0.0:
2022-02-13 01:27:15,722:ERROR:Traceback (most recent call last):
  File "C:\Users\TP\anaconda3\lib\site-packages\joblib\parallel.py", line 827, in dispatch_one_batch
    tasks = self._ready_batches.get(block=False)
  File "C:\Users\TP\anaconda3\lib\queue.py", line 167, in get
    raise Empty
_queue.Empty

During handling of the above exception, another exception occurred:

Traceback (most recent call last):
  File "C:\Users\TP\AppData\Roaming\Python\Python38\site-packages\pycaret\internal\tabular.py", line 2206, in compare_models
    model, model_fit_time = create_model_supervised(**create_model_args)
  File "C:\Users\TP\AppData\Roaming\Python\Python38\site-packages\pycaret\internal\tabular.py", line 3171, in create_model_supervised
    scores = cross_validate(
  File "C:\Users\TP\anaconda3\lib\site-packages\sklearn\utils\validation.py", line 72, in inner_f
    return f(**kwargs)
  File "C:\Users\TP\anaconda3\lib\site-packages\sklearn\model_selection\_validation.py", line 242, in cross_validate
    scores = parallel(
  File "C:\Users\TP\anaconda3\lib\site-packages\joblib\parallel.py", line 1048, in __call__
    if self.dispatch_one_batch(iterator):
  File "C:\Users\TP\anaconda3\lib\site-packages\joblib\parallel.py", line 838, in dispatch_one_batch
    islice = list(itertools.islice(iterator, big_batch_size))
  File "C:\Users\TP\anaconda3\lib\site-packages\sklearn\model_selection\_validation.py", line 242, in <genexpr>
    scores = parallel(
  File "C:\Users\TP\anaconda3\lib\site-packages\sklearn\model_selection\_split.py", line 336, in split
    for train, test in super().split(X, y, groups):
  File "C:\Users\TP\anaconda3\lib\site-packages\sklearn\model_selection\_split.py", line 80, in split
    for test_index in self._iter_test_masks(X, y, groups):
  File "C:\Users\TP\anaconda3\lib\site-packages\sklearn\model_selection\_split.py", line 697, in _iter_test_masks
    test_folds = self._make_test_folds(X, y)
  File "C:\Users\TP\anaconda3\lib\site-packages\sklearn\model_selection\_split.py", line 649, in _make_test_folds
    raise ValueError(
ValueError: Supported target types are: ('binary', 'multiclass'). Got 'continuous' instead.

During handling of the above exception, another exception occurred:

Traceback (most recent call last):
  File "C:\Users\TP\anaconda3\lib\site-packages\joblib\parallel.py", line 827, in dispatch_one_batch
    tasks = self._ready_batches.get(block=False)
  File "C:\Users\TP\anaconda3\lib\queue.py", line 167, in get
    raise Empty
_queue.Empty

During handling of the above exception, another exception occurred:

Traceback (most recent call last):
  File "C:\Users\TP\AppData\Roaming\Python\Python38\site-packages\pycaret\internal\tabular.py", line 2215, in compare_models
    model, model_fit_time = create_model_supervised(**create_model_args)
  File "C:\Users\TP\AppData\Roaming\Python\Python38\site-packages\pycaret\internal\tabular.py", line 3171, in create_model_supervised
    scores = cross_validate(
  File "C:\Users\TP\anaconda3\lib\site-packages\sklearn\utils\validation.py", line 72, in inner_f
    return f(**kwargs)
  File "C:\Users\TP\anaconda3\lib\site-packages\sklearn\model_selection\_validation.py", line 242, in cross_validate
    scores = parallel(
  File "C:\Users\TP\anaconda3\lib\site-packages\joblib\parallel.py", line 1048, in __call__
    if self.dispatch_one_batch(iterator):
  File "C:\Users\TP\anaconda3\lib\site-packages\joblib\parallel.py", line 838, in dispatch_one_batch
    islice = list(itertools.islice(iterator, big_batch_size))
  File "C:\Users\TP\anaconda3\lib\site-packages\sklearn\model_selection\_validation.py", line 242, in <genexpr>
    scores = parallel(
  File "C:\Users\TP\anaconda3\lib\site-packages\sklearn\model_selection\_split.py", line 336, in split
    for train, test in super().split(X, y, groups):
  File "C:\Users\TP\anaconda3\lib\site-packages\sklearn\model_selection\_split.py", line 80, in split
    for test_index in self._iter_test_masks(X, y, groups):
  File "C:\Users\TP\anaconda3\lib\site-packages\sklearn\model_selection\_split.py", line 697, in _iter_test_masks
    test_folds = self._make_test_folds(X, y)
  File "C:\Users\TP\anaconda3\lib\site-packages\sklearn\model_selection\_split.py", line 649, in _make_test_folds
    raise ValueError(
ValueError: Supported target types are: ('binary', 'multiclass'). Got 'continuous' instead.

2022-02-13 01:27:15,724:INFO:Initializing Decision Tree Classifier
2022-02-13 01:27:15,724:INFO:Total runtime is 0.007014588514963786 minutes
2022-02-13 01:27:15,734:INFO:SubProcess create_model() called ==================================
2022-02-13 01:27:15,735:INFO:Initializing create_model()
2022-02-13 01:27:15,735:INFO:create_model(estimator=dt, fold=StratifiedKFold(n_splits=10, random_state=None, shuffle=False), round=4, cross_validation=True, predict=True, fit_kwargs={}, groups=None, refit=False, verbose=False, system=False, metrics=None, add_to_model_list=True, probability_threshold=None, display=<pycaret.internal.Display.Display object at 0x000001CFB6416DF0>, kwargs={})
2022-02-13 01:27:15,735:INFO:Checking exceptions
2022-02-13 01:27:15,735:INFO:Importing libraries
2022-02-13 01:27:15,735:INFO:Copying training dataset
2022-02-13 01:27:15,738:INFO:Defining folds
2022-02-13 01:27:15,738:INFO:Declaring metric variables
2022-02-13 01:27:15,748:INFO:Importing untrained model
2022-02-13 01:27:15,761:INFO:Decision Tree Classifier Imported succesfully
2022-02-13 01:27:15,784:INFO:Starting cross validation
2022-02-13 01:27:15,785:INFO:Cross validating with StratifiedKFold(n_splits=10, random_state=None, shuffle=False), n_jobs=-1
2022-02-13 01:27:15,787:WARNING:create_model() for dt raised an exception or returned all 0.0, trying without fit_kwargs:
2022-02-13 01:27:15,788:WARNING:Traceback (most recent call last):
  File "C:\Users\TP\anaconda3\lib\site-packages\joblib\parallel.py", line 827, in dispatch_one_batch
    tasks = self._ready_batches.get(block=False)
  File "C:\Users\TP\anaconda3\lib\queue.py", line 167, in get
    raise Empty
_queue.Empty

During handling of the above exception, another exception occurred:

Traceback (most recent call last):
  File "C:\Users\TP\AppData\Roaming\Python\Python38\site-packages\pycaret\internal\tabular.py", line 2206, in compare_models
    model, model_fit_time = create_model_supervised(**create_model_args)
  File "C:\Users\TP\AppData\Roaming\Python\Python38\site-packages\pycaret\internal\tabular.py", line 3171, in create_model_supervised
    scores = cross_validate(
  File "C:\Users\TP\anaconda3\lib\site-packages\sklearn\utils\validation.py", line 72, in inner_f
    return f(**kwargs)
  File "C:\Users\TP\anaconda3\lib\site-packages\sklearn\model_selection\_validation.py", line 242, in cross_validate
    scores = parallel(
  File "C:\Users\TP\anaconda3\lib\site-packages\joblib\parallel.py", line 1048, in __call__
    if self.dispatch_one_batch(iterator):
  File "C:\Users\TP\anaconda3\lib\site-packages\joblib\parallel.py", line 838, in dispatch_one_batch
    islice = list(itertools.islice(iterator, big_batch_size))
  File "C:\Users\TP\anaconda3\lib\site-packages\sklearn\model_selection\_validation.py", line 242, in <genexpr>
    scores = parallel(
  File "C:\Users\TP\anaconda3\lib\site-packages\sklearn\model_selection\_split.py", line 336, in split
    for train, test in super().split(X, y, groups):
  File "C:\Users\TP\anaconda3\lib\site-packages\sklearn\model_selection\_split.py", line 80, in split
    for test_index in self._iter_test_masks(X, y, groups):
  File "C:\Users\TP\anaconda3\lib\site-packages\sklearn\model_selection\_split.py", line 697, in _iter_test_masks
    test_folds = self._make_test_folds(X, y)
  File "C:\Users\TP\anaconda3\lib\site-packages\sklearn\model_selection\_split.py", line 649, in _make_test_folds
    raise ValueError(
ValueError: Supported target types are: ('binary', 'multiclass'). Got 'continuous' instead.

2022-02-13 01:27:15,788:INFO:Initializing create_model()
2022-02-13 01:27:15,788:INFO:create_model(estimator=dt, fold=StratifiedKFold(n_splits=10, random_state=None, shuffle=False), round=4, cross_validation=True, predict=True, fit_kwargs={}, groups=None, refit=False, verbose=False, system=False, metrics=None, add_to_model_list=True, probability_threshold=None, display=<pycaret.internal.Display.Display object at 0x000001CFB6416DF0>, kwargs={})
2022-02-13 01:27:15,789:INFO:Checking exceptions
2022-02-13 01:27:15,789:INFO:Importing libraries
2022-02-13 01:27:15,789:INFO:Copying training dataset
2022-02-13 01:27:15,791:INFO:Defining folds
2022-02-13 01:27:15,791:INFO:Declaring metric variables
2022-02-13 01:27:15,800:INFO:Importing untrained model
2022-02-13 01:27:15,809:INFO:Decision Tree Classifier Imported succesfully
2022-02-13 01:27:15,830:INFO:Starting cross validation
2022-02-13 01:27:15,831:INFO:Cross validating with StratifiedKFold(n_splits=10, random_state=None, shuffle=False), n_jobs=-1
2022-02-13 01:27:15,833:ERROR:create_model() for dt raised an exception or returned all 0.0:
2022-02-13 01:27:15,836:ERROR:Traceback (most recent call last):
  File "C:\Users\TP\anaconda3\lib\site-packages\joblib\parallel.py", line 827, in dispatch_one_batch
    tasks = self._ready_batches.get(block=False)
  File "C:\Users\TP\anaconda3\lib\queue.py", line 167, in get
    raise Empty
_queue.Empty

During handling of the above exception, another exception occurred:

Traceback (most recent call last):
  File "C:\Users\TP\AppData\Roaming\Python\Python38\site-packages\pycaret\internal\tabular.py", line 2206, in compare_models
    model, model_fit_time = create_model_supervised(**create_model_args)
  File "C:\Users\TP\AppData\Roaming\Python\Python38\site-packages\pycaret\internal\tabular.py", line 3171, in create_model_supervised
    scores = cross_validate(
  File "C:\Users\TP\anaconda3\lib\site-packages\sklearn\utils\validation.py", line 72, in inner_f
    return f(**kwargs)
  File "C:\Users\TP\anaconda3\lib\site-packages\sklearn\model_selection\_validation.py", line 242, in cross_validate
    scores = parallel(
  File "C:\Users\TP\anaconda3\lib\site-packages\joblib\parallel.py", line 1048, in __call__
    if self.dispatch_one_batch(iterator):
  File "C:\Users\TP\anaconda3\lib\site-packages\joblib\parallel.py", line 838, in dispatch_one_batch
    islice = list(itertools.islice(iterator, big_batch_size))
  File "C:\Users\TP\anaconda3\lib\site-packages\sklearn\model_selection\_validation.py", line 242, in <genexpr>
    scores = parallel(
  File "C:\Users\TP\anaconda3\lib\site-packages\sklearn\model_selection\_split.py", line 336, in split
    for train, test in super().split(X, y, groups):
  File "C:\Users\TP\anaconda3\lib\site-packages\sklearn\model_selection\_split.py", line 80, in split
    for test_index in self._iter_test_masks(X, y, groups):
  File "C:\Users\TP\anaconda3\lib\site-packages\sklearn\model_selection\_split.py", line 697, in _iter_test_masks
    test_folds = self._make_test_folds(X, y)
  File "C:\Users\TP\anaconda3\lib\site-packages\sklearn\model_selection\_split.py", line 649, in _make_test_folds
    raise ValueError(
ValueError: Supported target types are: ('binary', 'multiclass'). Got 'continuous' instead.

During handling of the above exception, another exception occurred:

Traceback (most recent call last):
  File "C:\Users\TP\anaconda3\lib\site-packages\joblib\parallel.py", line 827, in dispatch_one_batch
    tasks = self._ready_batches.get(block=False)
  File "C:\Users\TP\anaconda3\lib\queue.py", line 167, in get
    raise Empty
_queue.Empty

During handling of the above exception, another exception occurred:

Traceback (most recent call last):
  File "C:\Users\TP\AppData\Roaming\Python\Python38\site-packages\pycaret\internal\tabular.py", line 2215, in compare_models
    model, model_fit_time = create_model_supervised(**create_model_args)
  File "C:\Users\TP\AppData\Roaming\Python\Python38\site-packages\pycaret\internal\tabular.py", line 3171, in create_model_supervised
    scores = cross_validate(
  File "C:\Users\TP\anaconda3\lib\site-packages\sklearn\utils\validation.py", line 72, in inner_f
    return f(**kwargs)
  File "C:\Users\TP\anaconda3\lib\site-packages\sklearn\model_selection\_validation.py", line 242, in cross_validate
    scores = parallel(
  File "C:\Users\TP\anaconda3\lib\site-packages\joblib\parallel.py", line 1048, in __call__
    if self.dispatch_one_batch(iterator):
  File "C:\Users\TP\anaconda3\lib\site-packages\joblib\parallel.py", line 838, in dispatch_one_batch
    islice = list(itertools.islice(iterator, big_batch_size))
  File "C:\Users\TP\anaconda3\lib\site-packages\sklearn\model_selection\_validation.py", line 242, in <genexpr>
    scores = parallel(
  File "C:\Users\TP\anaconda3\lib\site-packages\sklearn\model_selection\_split.py", line 336, in split
    for train, test in super().split(X, y, groups):
  File "C:\Users\TP\anaconda3\lib\site-packages\sklearn\model_selection\_split.py", line 80, in split
    for test_index in self._iter_test_masks(X, y, groups):
  File "C:\Users\TP\anaconda3\lib\site-packages\sklearn\model_selection\_split.py", line 697, in _iter_test_masks
    test_folds = self._make_test_folds(X, y)
  File "C:\Users\TP\anaconda3\lib\site-packages\sklearn\model_selection\_split.py", line 649, in _make_test_folds
    raise ValueError(
ValueError: Supported target types are: ('binary', 'multiclass'). Got 'continuous' instead.

2022-02-13 01:27:15,837:INFO:Initializing SVM - Linear Kernel
2022-02-13 01:27:15,837:INFO:Total runtime is 0.00889287789662679 minutes
2022-02-13 01:27:15,848:INFO:SubProcess create_model() called ==================================
2022-02-13 01:27:15,849:INFO:Initializing create_model()
2022-02-13 01:27:15,849:INFO:create_model(estimator=svm, fold=StratifiedKFold(n_splits=10, random_state=None, shuffle=False), round=4, cross_validation=True, predict=True, fit_kwargs={}, groups=None, refit=False, verbose=False, system=False, metrics=None, add_to_model_list=True, probability_threshold=None, display=<pycaret.internal.Display.Display object at 0x000001CFB6416DF0>, kwargs={})
2022-02-13 01:27:15,849:INFO:Checking exceptions
2022-02-13 01:27:15,850:INFO:Importing libraries
2022-02-13 01:27:15,850:INFO:Copying training dataset
2022-02-13 01:27:15,852:INFO:Defining folds
2022-02-13 01:27:15,852:INFO:Declaring metric variables
2022-02-13 01:27:15,861:INFO:Importing untrained model
2022-02-13 01:27:15,872:INFO:SVM - Linear Kernel Imported succesfully
2022-02-13 01:27:15,896:INFO:Starting cross validation
2022-02-13 01:27:15,897:INFO:Cross validating with StratifiedKFold(n_splits=10, random_state=None, shuffle=False), n_jobs=-1
2022-02-13 01:27:15,899:WARNING:create_model() for svm raised an exception or returned all 0.0, trying without fit_kwargs:
2022-02-13 01:27:15,901:WARNING:Traceback (most recent call last):
  File "C:\Users\TP\anaconda3\lib\site-packages\joblib\parallel.py", line 827, in dispatch_one_batch
    tasks = self._ready_batches.get(block=False)
  File "C:\Users\TP\anaconda3\lib\queue.py", line 167, in get
    raise Empty
_queue.Empty

During handling of the above exception, another exception occurred:

Traceback (most recent call last):
  File "C:\Users\TP\AppData\Roaming\Python\Python38\site-packages\pycaret\internal\tabular.py", line 2206, in compare_models
    model, model_fit_time = create_model_supervised(**create_model_args)
  File "C:\Users\TP\AppData\Roaming\Python\Python38\site-packages\pycaret\internal\tabular.py", line 3171, in create_model_supervised
    scores = cross_validate(
  File "C:\Users\TP\anaconda3\lib\site-packages\sklearn\utils\validation.py", line 72, in inner_f
    return f(**kwargs)
  File "C:\Users\TP\anaconda3\lib\site-packages\sklearn\model_selection\_validation.py", line 242, in cross_validate
    scores = parallel(
  File "C:\Users\TP\anaconda3\lib\site-packages\joblib\parallel.py", line 1048, in __call__
    if self.dispatch_one_batch(iterator):
  File "C:\Users\TP\anaconda3\lib\site-packages\joblib\parallel.py", line 838, in dispatch_one_batch
    islice = list(itertools.islice(iterator, big_batch_size))
  File "C:\Users\TP\anaconda3\lib\site-packages\sklearn\model_selection\_validation.py", line 242, in <genexpr>
    scores = parallel(
  File "C:\Users\TP\anaconda3\lib\site-packages\sklearn\model_selection\_split.py", line 336, in split
    for train, test in super().split(X, y, groups):
  File "C:\Users\TP\anaconda3\lib\site-packages\sklearn\model_selection\_split.py", line 80, in split
    for test_index in self._iter_test_masks(X, y, groups):
  File "C:\Users\TP\anaconda3\lib\site-packages\sklearn\model_selection\_split.py", line 697, in _iter_test_masks
    test_folds = self._make_test_folds(X, y)
  File "C:\Users\TP\anaconda3\lib\site-packages\sklearn\model_selection\_split.py", line 649, in _make_test_folds
    raise ValueError(
ValueError: Supported target types are: ('binary', 'multiclass'). Got 'continuous' instead.

2022-02-13 01:27:15,901:INFO:Initializing create_model()
2022-02-13 01:27:15,901:INFO:create_model(estimator=svm, fold=StratifiedKFold(n_splits=10, random_state=None, shuffle=False), round=4, cross_validation=True, predict=True, fit_kwargs={}, groups=None, refit=False, verbose=False, system=False, metrics=None, add_to_model_list=True, probability_threshold=None, display=<pycaret.internal.Display.Display object at 0x000001CFB6416DF0>, kwargs={})
2022-02-13 01:27:15,901:INFO:Checking exceptions
2022-02-13 01:27:15,901:INFO:Importing libraries
2022-02-13 01:27:15,901:INFO:Copying training dataset
2022-02-13 01:27:15,903:INFO:Defining folds
2022-02-13 01:27:15,903:INFO:Declaring metric variables
2022-02-13 01:27:15,913:INFO:Importing untrained model
2022-02-13 01:27:15,927:INFO:SVM - Linear Kernel Imported succesfully
2022-02-13 01:27:15,951:INFO:Starting cross validation
2022-02-13 01:27:15,952:INFO:Cross validating with StratifiedKFold(n_splits=10, random_state=None, shuffle=False), n_jobs=-1
2022-02-13 01:27:15,954:ERROR:create_model() for svm raised an exception or returned all 0.0:
2022-02-13 01:27:15,956:ERROR:Traceback (most recent call last):
  File "C:\Users\TP\anaconda3\lib\site-packages\joblib\parallel.py", line 827, in dispatch_one_batch
    tasks = self._ready_batches.get(block=False)
  File "C:\Users\TP\anaconda3\lib\queue.py", line 167, in get
    raise Empty
_queue.Empty

During handling of the above exception, another exception occurred:

Traceback (most recent call last):
  File "C:\Users\TP\AppData\Roaming\Python\Python38\site-packages\pycaret\internal\tabular.py", line 2206, in compare_models
    model, model_fit_time = create_model_supervised(**create_model_args)
  File "C:\Users\TP\AppData\Roaming\Python\Python38\site-packages\pycaret\internal\tabular.py", line 3171, in create_model_supervised
    scores = cross_validate(
  File "C:\Users\TP\anaconda3\lib\site-packages\sklearn\utils\validation.py", line 72, in inner_f
    return f(**kwargs)
  File "C:\Users\TP\anaconda3\lib\site-packages\sklearn\model_selection\_validation.py", line 242, in cross_validate
    scores = parallel(
  File "C:\Users\TP\anaconda3\lib\site-packages\joblib\parallel.py", line 1048, in __call__
    if self.dispatch_one_batch(iterator):
  File "C:\Users\TP\anaconda3\lib\site-packages\joblib\parallel.py", line 838, in dispatch_one_batch
    islice = list(itertools.islice(iterator, big_batch_size))
  File "C:\Users\TP\anaconda3\lib\site-packages\sklearn\model_selection\_validation.py", line 242, in <genexpr>
    scores = parallel(
  File "C:\Users\TP\anaconda3\lib\site-packages\sklearn\model_selection\_split.py", line 336, in split
    for train, test in super().split(X, y, groups):
  File "C:\Users\TP\anaconda3\lib\site-packages\sklearn\model_selection\_split.py", line 80, in split
    for test_index in self._iter_test_masks(X, y, groups):
  File "C:\Users\TP\anaconda3\lib\site-packages\sklearn\model_selection\_split.py", line 697, in _iter_test_masks
    test_folds = self._make_test_folds(X, y)
  File "C:\Users\TP\anaconda3\lib\site-packages\sklearn\model_selection\_split.py", line 649, in _make_test_folds
    raise ValueError(
ValueError: Supported target types are: ('binary', 'multiclass'). Got 'continuous' instead.

During handling of the above exception, another exception occurred:

Traceback (most recent call last):
  File "C:\Users\TP\anaconda3\lib\site-packages\joblib\parallel.py", line 827, in dispatch_one_batch
    tasks = self._ready_batches.get(block=False)
  File "C:\Users\TP\anaconda3\lib\queue.py", line 167, in get
    raise Empty
_queue.Empty

During handling of the above exception, another exception occurred:

Traceback (most recent call last):
  File "C:\Users\TP\AppData\Roaming\Python\Python38\site-packages\pycaret\internal\tabular.py", line 2215, in compare_models
    model, model_fit_time = create_model_supervised(**create_model_args)
  File "C:\Users\TP\AppData\Roaming\Python\Python38\site-packages\pycaret\internal\tabular.py", line 3171, in create_model_supervised
    scores = cross_validate(
  File "C:\Users\TP\anaconda3\lib\site-packages\sklearn\utils\validation.py", line 72, in inner_f
    return f(**kwargs)
  File "C:\Users\TP\anaconda3\lib\site-packages\sklearn\model_selection\_validation.py", line 242, in cross_validate
    scores = parallel(
  File "C:\Users\TP\anaconda3\lib\site-packages\joblib\parallel.py", line 1048, in __call__
    if self.dispatch_one_batch(iterator):
  File "C:\Users\TP\anaconda3\lib\site-packages\joblib\parallel.py", line 838, in dispatch_one_batch
    islice = list(itertools.islice(iterator, big_batch_size))
  File "C:\Users\TP\anaconda3\lib\site-packages\sklearn\model_selection\_validation.py", line 242, in <genexpr>
    scores = parallel(
  File "C:\Users\TP\anaconda3\lib\site-packages\sklearn\model_selection\_split.py", line 336, in split
    for train, test in super().split(X, y, groups):
  File "C:\Users\TP\anaconda3\lib\site-packages\sklearn\model_selection\_split.py", line 80, in split
    for test_index in self._iter_test_masks(X, y, groups):
  File "C:\Users\TP\anaconda3\lib\site-packages\sklearn\model_selection\_split.py", line 697, in _iter_test_masks
    test_folds = self._make_test_folds(X, y)
  File "C:\Users\TP\anaconda3\lib\site-packages\sklearn\model_selection\_split.py", line 649, in _make_test_folds
    raise ValueError(
ValueError: Supported target types are: ('binary', 'multiclass'). Got 'continuous' instead.

2022-02-13 01:27:15,957:INFO:Initializing Ridge Classifier
2022-02-13 01:27:15,957:INFO:Total runtime is 0.010887543360392254 minutes
2022-02-13 01:27:15,970:INFO:SubProcess create_model() called ==================================
2022-02-13 01:27:15,970:INFO:Initializing create_model()
2022-02-13 01:27:15,970:INFO:create_model(estimator=ridge, fold=StratifiedKFold(n_splits=10, random_state=None, shuffle=False), round=4, cross_validation=True, predict=True, fit_kwargs={}, groups=None, refit=False, verbose=False, system=False, metrics=None, add_to_model_list=True, probability_threshold=None, display=<pycaret.internal.Display.Display object at 0x000001CFB6416DF0>, kwargs={})
2022-02-13 01:27:15,971:INFO:Checking exceptions
2022-02-13 01:27:15,971:INFO:Importing libraries
2022-02-13 01:27:15,971:INFO:Copying training dataset
2022-02-13 01:27:15,973:INFO:Defining folds
2022-02-13 01:27:15,973:INFO:Declaring metric variables
2022-02-13 01:27:15,984:INFO:Importing untrained model
2022-02-13 01:27:15,993:INFO:Ridge Classifier Imported succesfully
2022-02-13 01:27:16,017:INFO:Starting cross validation
2022-02-13 01:27:16,017:INFO:Cross validating with StratifiedKFold(n_splits=10, random_state=None, shuffle=False), n_jobs=-1
2022-02-13 01:27:16,019:WARNING:create_model() for ridge raised an exception or returned all 0.0, trying without fit_kwargs:
2022-02-13 01:27:16,020:WARNING:Traceback (most recent call last):
  File "C:\Users\TP\anaconda3\lib\site-packages\joblib\parallel.py", line 827, in dispatch_one_batch
    tasks = self._ready_batches.get(block=False)
  File "C:\Users\TP\anaconda3\lib\queue.py", line 167, in get
    raise Empty
_queue.Empty

During handling of the above exception, another exception occurred:

Traceback (most recent call last):
  File "C:\Users\TP\AppData\Roaming\Python\Python38\site-packages\pycaret\internal\tabular.py", line 2206, in compare_models
    model, model_fit_time = create_model_supervised(**create_model_args)
  File "C:\Users\TP\AppData\Roaming\Python\Python38\site-packages\pycaret\internal\tabular.py", line 3171, in create_model_supervised
    scores = cross_validate(
  File "C:\Users\TP\anaconda3\lib\site-packages\sklearn\utils\validation.py", line 72, in inner_f
    return f(**kwargs)
  File "C:\Users\TP\anaconda3\lib\site-packages\sklearn\model_selection\_validation.py", line 242, in cross_validate
    scores = parallel(
  File "C:\Users\TP\anaconda3\lib\site-packages\joblib\parallel.py", line 1048, in __call__
    if self.dispatch_one_batch(iterator):
  File "C:\Users\TP\anaconda3\lib\site-packages\joblib\parallel.py", line 838, in dispatch_one_batch
    islice = list(itertools.islice(iterator, big_batch_size))
  File "C:\Users\TP\anaconda3\lib\site-packages\sklearn\model_selection\_validation.py", line 242, in <genexpr>
    scores = parallel(
  File "C:\Users\TP\anaconda3\lib\site-packages\sklearn\model_selection\_split.py", line 336, in split
    for train, test in super().split(X, y, groups):
  File "C:\Users\TP\anaconda3\lib\site-packages\sklearn\model_selection\_split.py", line 80, in split
    for test_index in self._iter_test_masks(X, y, groups):
  File "C:\Users\TP\anaconda3\lib\site-packages\sklearn\model_selection\_split.py", line 697, in _iter_test_masks
    test_folds = self._make_test_folds(X, y)
  File "C:\Users\TP\anaconda3\lib\site-packages\sklearn\model_selection\_split.py", line 649, in _make_test_folds
    raise ValueError(
ValueError: Supported target types are: ('binary', 'multiclass'). Got 'continuous' instead.

2022-02-13 01:27:16,020:INFO:Initializing create_model()
2022-02-13 01:27:16,020:INFO:create_model(estimator=ridge, fold=StratifiedKFold(n_splits=10, random_state=None, shuffle=False), round=4, cross_validation=True, predict=True, fit_kwargs={}, groups=None, refit=False, verbose=False, system=False, metrics=None, add_to_model_list=True, probability_threshold=None, display=<pycaret.internal.Display.Display object at 0x000001CFB6416DF0>, kwargs={})
2022-02-13 01:27:16,021:INFO:Checking exceptions
2022-02-13 01:27:16,021:INFO:Importing libraries
2022-02-13 01:27:16,021:INFO:Copying training dataset
2022-02-13 01:27:16,022:INFO:Defining folds
2022-02-13 01:27:16,022:INFO:Declaring metric variables
2022-02-13 01:27:16,039:INFO:Importing untrained model
2022-02-13 01:27:16,051:INFO:Ridge Classifier Imported succesfully
2022-02-13 01:27:16,077:INFO:Starting cross validation
2022-02-13 01:27:16,077:INFO:Cross validating with StratifiedKFold(n_splits=10, random_state=None, shuffle=False), n_jobs=-1
2022-02-13 01:27:16,079:ERROR:create_model() for ridge raised an exception or returned all 0.0:
2022-02-13 01:27:16,084:ERROR:Traceback (most recent call last):
  File "C:\Users\TP\anaconda3\lib\site-packages\joblib\parallel.py", line 827, in dispatch_one_batch
    tasks = self._ready_batches.get(block=False)
  File "C:\Users\TP\anaconda3\lib\queue.py", line 167, in get
    raise Empty
_queue.Empty

During handling of the above exception, another exception occurred:

Traceback (most recent call last):
  File "C:\Users\TP\AppData\Roaming\Python\Python38\site-packages\pycaret\internal\tabular.py", line 2206, in compare_models
    model, model_fit_time = create_model_supervised(**create_model_args)
  File "C:\Users\TP\AppData\Roaming\Python\Python38\site-packages\pycaret\internal\tabular.py", line 3171, in create_model_supervised
    scores = cross_validate(
  File "C:\Users\TP\anaconda3\lib\site-packages\sklearn\utils\validation.py", line 72, in inner_f
    return f(**kwargs)
  File "C:\Users\TP\anaconda3\lib\site-packages\sklearn\model_selection\_validation.py", line 242, in cross_validate
    scores = parallel(
  File "C:\Users\TP\anaconda3\lib\site-packages\joblib\parallel.py", line 1048, in __call__
    if self.dispatch_one_batch(iterator):
  File "C:\Users\TP\anaconda3\lib\site-packages\joblib\parallel.py", line 838, in dispatch_one_batch
    islice = list(itertools.islice(iterator, big_batch_size))
  File "C:\Users\TP\anaconda3\lib\site-packages\sklearn\model_selection\_validation.py", line 242, in <genexpr>
    scores = parallel(
  File "C:\Users\TP\anaconda3\lib\site-packages\sklearn\model_selection\_split.py", line 336, in split
    for train, test in super().split(X, y, groups):
  File "C:\Users\TP\anaconda3\lib\site-packages\sklearn\model_selection\_split.py", line 80, in split
    for test_index in self._iter_test_masks(X, y, groups):
  File "C:\Users\TP\anaconda3\lib\site-packages\sklearn\model_selection\_split.py", line 697, in _iter_test_masks
    test_folds = self._make_test_folds(X, y)
  File "C:\Users\TP\anaconda3\lib\site-packages\sklearn\model_selection\_split.py", line 649, in _make_test_folds
    raise ValueError(
ValueError: Supported target types are: ('binary', 'multiclass'). Got 'continuous' instead.

During handling of the above exception, another exception occurred:

Traceback (most recent call last):
  File "C:\Users\TP\anaconda3\lib\site-packages\joblib\parallel.py", line 827, in dispatch_one_batch
    tasks = self._ready_batches.get(block=False)
  File "C:\Users\TP\anaconda3\lib\queue.py", line 167, in get
    raise Empty
_queue.Empty

During handling of the above exception, another exception occurred:

Traceback (most recent call last):
  File "C:\Users\TP\AppData\Roaming\Python\Python38\site-packages\pycaret\internal\tabular.py", line 2215, in compare_models
    model, model_fit_time = create_model_supervised(**create_model_args)
  File "C:\Users\TP\AppData\Roaming\Python\Python38\site-packages\pycaret\internal\tabular.py", line 3171, in create_model_supervised
    scores = cross_validate(
  File "C:\Users\TP\anaconda3\lib\site-packages\sklearn\utils\validation.py", line 72, in inner_f
    return f(**kwargs)
  File "C:\Users\TP\anaconda3\lib\site-packages\sklearn\model_selection\_validation.py", line 242, in cross_validate
    scores = parallel(
  File "C:\Users\TP\anaconda3\lib\site-packages\joblib\parallel.py", line 1048, in __call__
    if self.dispatch_one_batch(iterator):
  File "C:\Users\TP\anaconda3\lib\site-packages\joblib\parallel.py", line 838, in dispatch_one_batch
    islice = list(itertools.islice(iterator, big_batch_size))
  File "C:\Users\TP\anaconda3\lib\site-packages\sklearn\model_selection\_validation.py", line 242, in <genexpr>
    scores = parallel(
  File "C:\Users\TP\anaconda3\lib\site-packages\sklearn\model_selection\_split.py", line 336, in split
    for train, test in super().split(X, y, groups):
  File "C:\Users\TP\anaconda3\lib\site-packages\sklearn\model_selection\_split.py", line 80, in split
    for test_index in self._iter_test_masks(X, y, groups):
  File "C:\Users\TP\anaconda3\lib\site-packages\sklearn\model_selection\_split.py", line 697, in _iter_test_masks
    test_folds = self._make_test_folds(X, y)
  File "C:\Users\TP\anaconda3\lib\site-packages\sklearn\model_selection\_split.py", line 649, in _make_test_folds
    raise ValueError(
ValueError: Supported target types are: ('binary', 'multiclass'). Got 'continuous' instead.

2022-02-13 01:27:16,085:INFO:Initializing Random Forest Classifier
2022-02-13 01:27:16,085:INFO:Total runtime is 0.0130239208539327 minutes
2022-02-13 01:27:16,095:INFO:SubProcess create_model() called ==================================
2022-02-13 01:27:16,095:INFO:Initializing create_model()
2022-02-13 01:27:16,095:INFO:create_model(estimator=rf, fold=StratifiedKFold(n_splits=10, random_state=None, shuffle=False), round=4, cross_validation=True, predict=True, fit_kwargs={}, groups=None, refit=False, verbose=False, system=False, metrics=None, add_to_model_list=True, probability_threshold=None, display=<pycaret.internal.Display.Display object at 0x000001CFB6416DF0>, kwargs={})
2022-02-13 01:27:16,096:INFO:Checking exceptions
2022-02-13 01:27:16,096:INFO:Importing libraries
2022-02-13 01:27:16,096:INFO:Copying training dataset
2022-02-13 01:27:16,099:INFO:Defining folds
2022-02-13 01:27:16,099:INFO:Declaring metric variables
2022-02-13 01:27:16,109:INFO:Importing untrained model
2022-02-13 01:27:16,122:INFO:Random Forest Classifier Imported succesfully
2022-02-13 01:27:16,143:INFO:Starting cross validation
2022-02-13 01:27:16,144:INFO:Cross validating with StratifiedKFold(n_splits=10, random_state=None, shuffle=False), n_jobs=-1
2022-02-13 01:27:16,147:WARNING:create_model() for rf raised an exception or returned all 0.0, trying without fit_kwargs:
2022-02-13 01:27:16,149:WARNING:Traceback (most recent call last):
  File "C:\Users\TP\anaconda3\lib\site-packages\joblib\parallel.py", line 827, in dispatch_one_batch
    tasks = self._ready_batches.get(block=False)
  File "C:\Users\TP\anaconda3\lib\queue.py", line 167, in get
    raise Empty
_queue.Empty

During handling of the above exception, another exception occurred:

Traceback (most recent call last):
  File "C:\Users\TP\AppData\Roaming\Python\Python38\site-packages\pycaret\internal\tabular.py", line 2206, in compare_models
    model, model_fit_time = create_model_supervised(**create_model_args)
  File "C:\Users\TP\AppData\Roaming\Python\Python38\site-packages\pycaret\internal\tabular.py", line 3171, in create_model_supervised
    scores = cross_validate(
  File "C:\Users\TP\anaconda3\lib\site-packages\sklearn\utils\validation.py", line 72, in inner_f
    return f(**kwargs)
  File "C:\Users\TP\anaconda3\lib\site-packages\sklearn\model_selection\_validation.py", line 242, in cross_validate
    scores = parallel(
  File "C:\Users\TP\anaconda3\lib\site-packages\joblib\parallel.py", line 1048, in __call__
    if self.dispatch_one_batch(iterator):
  File "C:\Users\TP\anaconda3\lib\site-packages\joblib\parallel.py", line 838, in dispatch_one_batch
    islice = list(itertools.islice(iterator, big_batch_size))
  File "C:\Users\TP\anaconda3\lib\site-packages\sklearn\model_selection\_validation.py", line 242, in <genexpr>
    scores = parallel(
  File "C:\Users\TP\anaconda3\lib\site-packages\sklearn\model_selection\_split.py", line 336, in split
    for train, test in super().split(X, y, groups):
  File "C:\Users\TP\anaconda3\lib\site-packages\sklearn\model_selection\_split.py", line 80, in split
    for test_index in self._iter_test_masks(X, y, groups):
  File "C:\Users\TP\anaconda3\lib\site-packages\sklearn\model_selection\_split.py", line 697, in _iter_test_masks
    test_folds = self._make_test_folds(X, y)
  File "C:\Users\TP\anaconda3\lib\site-packages\sklearn\model_selection\_split.py", line 649, in _make_test_folds
    raise ValueError(
ValueError: Supported target types are: ('binary', 'multiclass'). Got 'continuous' instead.

2022-02-13 01:27:16,149:INFO:Initializing create_model()
2022-02-13 01:27:16,149:INFO:create_model(estimator=rf, fold=StratifiedKFold(n_splits=10, random_state=None, shuffle=False), round=4, cross_validation=True, predict=True, fit_kwargs={}, groups=None, refit=False, verbose=False, system=False, metrics=None, add_to_model_list=True, probability_threshold=None, display=<pycaret.internal.Display.Display object at 0x000001CFB6416DF0>, kwargs={})
2022-02-13 01:27:16,149:INFO:Checking exceptions
2022-02-13 01:27:16,149:INFO:Importing libraries
2022-02-13 01:27:16,149:INFO:Copying training dataset
2022-02-13 01:27:16,151:INFO:Defining folds
2022-02-13 01:27:16,152:INFO:Declaring metric variables
2022-02-13 01:27:16,163:INFO:Importing untrained model
2022-02-13 01:27:16,176:INFO:Random Forest Classifier Imported succesfully
2022-02-13 01:27:16,202:INFO:Starting cross validation
2022-02-13 01:27:16,203:INFO:Cross validating with StratifiedKFold(n_splits=10, random_state=None, shuffle=False), n_jobs=-1
2022-02-13 01:27:16,514:ERROR:create_model() for rf raised an exception or returned all 0.0:
2022-02-13 01:27:16,517:ERROR:Traceback (most recent call last):
  File "C:\Users\TP\anaconda3\lib\site-packages\joblib\parallel.py", line 827, in dispatch_one_batch
    tasks = self._ready_batches.get(block=False)
  File "C:\Users\TP\anaconda3\lib\queue.py", line 167, in get
    raise Empty
_queue.Empty

During handling of the above exception, another exception occurred:

Traceback (most recent call last):
  File "C:\Users\TP\AppData\Roaming\Python\Python38\site-packages\pycaret\internal\tabular.py", line 2206, in compare_models
    model, model_fit_time = create_model_supervised(**create_model_args)
  File "C:\Users\TP\AppData\Roaming\Python\Python38\site-packages\pycaret\internal\tabular.py", line 3171, in create_model_supervised
    scores = cross_validate(
  File "C:\Users\TP\anaconda3\lib\site-packages\sklearn\utils\validation.py", line 72, in inner_f
    return f(**kwargs)
  File "C:\Users\TP\anaconda3\lib\site-packages\sklearn\model_selection\_validation.py", line 242, in cross_validate
    scores = parallel(
  File "C:\Users\TP\anaconda3\lib\site-packages\joblib\parallel.py", line 1048, in __call__
    if self.dispatch_one_batch(iterator):
  File "C:\Users\TP\anaconda3\lib\site-packages\joblib\parallel.py", line 838, in dispatch_one_batch
    islice = list(itertools.islice(iterator, big_batch_size))
  File "C:\Users\TP\anaconda3\lib\site-packages\sklearn\model_selection\_validation.py", line 242, in <genexpr>
    scores = parallel(
  File "C:\Users\TP\anaconda3\lib\site-packages\sklearn\model_selection\_split.py", line 336, in split
    for train, test in super().split(X, y, groups):
  File "C:\Users\TP\anaconda3\lib\site-packages\sklearn\model_selection\_split.py", line 80, in split
    for test_index in self._iter_test_masks(X, y, groups):
  File "C:\Users\TP\anaconda3\lib\site-packages\sklearn\model_selection\_split.py", line 697, in _iter_test_masks
    test_folds = self._make_test_folds(X, y)
  File "C:\Users\TP\anaconda3\lib\site-packages\sklearn\model_selection\_split.py", line 649, in _make_test_folds
    raise ValueError(
ValueError: Supported target types are: ('binary', 'multiclass'). Got 'continuous' instead.

During handling of the above exception, another exception occurred:

Traceback (most recent call last):
  File "C:\Users\TP\anaconda3\lib\site-packages\joblib\parallel.py", line 827, in dispatch_one_batch
    tasks = self._ready_batches.get(block=False)
  File "C:\Users\TP\anaconda3\lib\queue.py", line 167, in get
    raise Empty
_queue.Empty

During handling of the above exception, another exception occurred:

Traceback (most recent call last):
  File "C:\Users\TP\AppData\Roaming\Python\Python38\site-packages\pycaret\internal\tabular.py", line 2215, in compare_models
    model, model_fit_time = create_model_supervised(**create_model_args)
  File "C:\Users\TP\AppData\Roaming\Python\Python38\site-packages\pycaret\internal\tabular.py", line 3171, in create_model_supervised
    scores = cross_validate(
  File "C:\Users\TP\anaconda3\lib\site-packages\sklearn\utils\validation.py", line 72, in inner_f
    return f(**kwargs)
  File "C:\Users\TP\anaconda3\lib\site-packages\sklearn\model_selection\_validation.py", line 242, in cross_validate
    scores = parallel(
  File "C:\Users\TP\anaconda3\lib\site-packages\joblib\parallel.py", line 1048, in __call__
    if self.dispatch_one_batch(iterator):
  File "C:\Users\TP\anaconda3\lib\site-packages\joblib\parallel.py", line 838, in dispatch_one_batch
    islice = list(itertools.islice(iterator, big_batch_size))
  File "C:\Users\TP\anaconda3\lib\site-packages\sklearn\model_selection\_validation.py", line 242, in <genexpr>
    scores = parallel(
  File "C:\Users\TP\anaconda3\lib\site-packages\sklearn\model_selection\_split.py", line 336, in split
    for train, test in super().split(X, y, groups):
  File "C:\Users\TP\anaconda3\lib\site-packages\sklearn\model_selection\_split.py", line 80, in split
    for test_index in self._iter_test_masks(X, y, groups):
  File "C:\Users\TP\anaconda3\lib\site-packages\sklearn\model_selection\_split.py", line 697, in _iter_test_masks
    test_folds = self._make_test_folds(X, y)
  File "C:\Users\TP\anaconda3\lib\site-packages\sklearn\model_selection\_split.py", line 649, in _make_test_folds
    raise ValueError(
ValueError: Supported target types are: ('binary', 'multiclass'). Got 'continuous' instead.

2022-02-13 01:27:16,518:INFO:Initializing Quadratic Discriminant Analysis
2022-02-13 01:27:16,518:INFO:Total runtime is 0.02024476528167725 minutes
2022-02-13 01:27:16,526:INFO:SubProcess create_model() called ==================================
2022-02-13 01:27:16,527:INFO:Initializing create_model()
2022-02-13 01:27:16,527:INFO:create_model(estimator=qda, fold=StratifiedKFold(n_splits=10, random_state=None, shuffle=False), round=4, cross_validation=True, predict=True, fit_kwargs={}, groups=None, refit=False, verbose=False, system=False, metrics=None, add_to_model_list=True, probability_threshold=None, display=<pycaret.internal.Display.Display object at 0x000001CFB6416DF0>, kwargs={})
2022-02-13 01:27:16,527:INFO:Checking exceptions
2022-02-13 01:27:16,527:INFO:Importing libraries
2022-02-13 01:27:16,527:INFO:Copying training dataset
2022-02-13 01:27:16,529:INFO:Defining folds
2022-02-13 01:27:16,529:INFO:Declaring metric variables
2022-02-13 01:27:16,537:INFO:Importing untrained model
2022-02-13 01:27:16,548:INFO:Quadratic Discriminant Analysis Imported succesfully
2022-02-13 01:27:16,566:INFO:Starting cross validation
2022-02-13 01:27:16,567:INFO:Cross validating with StratifiedKFold(n_splits=10, random_state=None, shuffle=False), n_jobs=-1
2022-02-13 01:27:16,569:WARNING:create_model() for qda raised an exception or returned all 0.0, trying without fit_kwargs:
2022-02-13 01:27:16,570:WARNING:Traceback (most recent call last):
  File "C:\Users\TP\anaconda3\lib\site-packages\joblib\parallel.py", line 827, in dispatch_one_batch
    tasks = self._ready_batches.get(block=False)
  File "C:\Users\TP\anaconda3\lib\queue.py", line 167, in get
    raise Empty
_queue.Empty

During handling of the above exception, another exception occurred:

Traceback (most recent call last):
  File "C:\Users\TP\AppData\Roaming\Python\Python38\site-packages\pycaret\internal\tabular.py", line 2206, in compare_models
    model, model_fit_time = create_model_supervised(**create_model_args)
  File "C:\Users\TP\AppData\Roaming\Python\Python38\site-packages\pycaret\internal\tabular.py", line 3171, in create_model_supervised
    scores = cross_validate(
  File "C:\Users\TP\anaconda3\lib\site-packages\sklearn\utils\validation.py", line 72, in inner_f
    return f(**kwargs)
  File "C:\Users\TP\anaconda3\lib\site-packages\sklearn\model_selection\_validation.py", line 242, in cross_validate
    scores = parallel(
  File "C:\Users\TP\anaconda3\lib\site-packages\joblib\parallel.py", line 1048, in __call__
    if self.dispatch_one_batch(iterator):
  File "C:\Users\TP\anaconda3\lib\site-packages\joblib\parallel.py", line 838, in dispatch_one_batch
    islice = list(itertools.islice(iterator, big_batch_size))
  File "C:\Users\TP\anaconda3\lib\site-packages\sklearn\model_selection\_validation.py", line 242, in <genexpr>
    scores = parallel(
  File "C:\Users\TP\anaconda3\lib\site-packages\sklearn\model_selection\_split.py", line 336, in split
    for train, test in super().split(X, y, groups):
  File "C:\Users\TP\anaconda3\lib\site-packages\sklearn\model_selection\_split.py", line 80, in split
    for test_index in self._iter_test_masks(X, y, groups):
  File "C:\Users\TP\anaconda3\lib\site-packages\sklearn\model_selection\_split.py", line 697, in _iter_test_masks
    test_folds = self._make_test_folds(X, y)
  File "C:\Users\TP\anaconda3\lib\site-packages\sklearn\model_selection\_split.py", line 649, in _make_test_folds
    raise ValueError(
ValueError: Supported target types are: ('binary', 'multiclass'). Got 'continuous' instead.

2022-02-13 01:27:16,570:INFO:Initializing create_model()
2022-02-13 01:27:16,570:INFO:create_model(estimator=qda, fold=StratifiedKFold(n_splits=10, random_state=None, shuffle=False), round=4, cross_validation=True, predict=True, fit_kwargs={}, groups=None, refit=False, verbose=False, system=False, metrics=None, add_to_model_list=True, probability_threshold=None, display=<pycaret.internal.Display.Display object at 0x000001CFB6416DF0>, kwargs={})
2022-02-13 01:27:16,571:INFO:Checking exceptions
2022-02-13 01:27:16,571:INFO:Importing libraries
2022-02-13 01:27:16,571:INFO:Copying training dataset
2022-02-13 01:27:16,573:INFO:Defining folds
2022-02-13 01:27:16,573:INFO:Declaring metric variables
2022-02-13 01:27:16,582:INFO:Importing untrained model
2022-02-13 01:27:16,593:INFO:Quadratic Discriminant Analysis Imported succesfully
2022-02-13 01:27:16,613:INFO:Starting cross validation
2022-02-13 01:27:16,614:INFO:Cross validating with StratifiedKFold(n_splits=10, random_state=None, shuffle=False), n_jobs=-1
2022-02-13 01:27:16,616:ERROR:create_model() for qda raised an exception or returned all 0.0:
2022-02-13 01:27:16,620:ERROR:Traceback (most recent call last):
  File "C:\Users\TP\anaconda3\lib\site-packages\joblib\parallel.py", line 827, in dispatch_one_batch
    tasks = self._ready_batches.get(block=False)
  File "C:\Users\TP\anaconda3\lib\queue.py", line 167, in get
    raise Empty
_queue.Empty

During handling of the above exception, another exception occurred:

Traceback (most recent call last):
  File "C:\Users\TP\AppData\Roaming\Python\Python38\site-packages\pycaret\internal\tabular.py", line 2206, in compare_models
    model, model_fit_time = create_model_supervised(**create_model_args)
  File "C:\Users\TP\AppData\Roaming\Python\Python38\site-packages\pycaret\internal\tabular.py", line 3171, in create_model_supervised
    scores = cross_validate(
  File "C:\Users\TP\anaconda3\lib\site-packages\sklearn\utils\validation.py", line 72, in inner_f
    return f(**kwargs)
  File "C:\Users\TP\anaconda3\lib\site-packages\sklearn\model_selection\_validation.py", line 242, in cross_validate
    scores = parallel(
  File "C:\Users\TP\anaconda3\lib\site-packages\joblib\parallel.py", line 1048, in __call__
    if self.dispatch_one_batch(iterator):
  File "C:\Users\TP\anaconda3\lib\site-packages\joblib\parallel.py", line 838, in dispatch_one_batch
    islice = list(itertools.islice(iterator, big_batch_size))
  File "C:\Users\TP\anaconda3\lib\site-packages\sklearn\model_selection\_validation.py", line 242, in <genexpr>
    scores = parallel(
  File "C:\Users\TP\anaconda3\lib\site-packages\sklearn\model_selection\_split.py", line 336, in split
    for train, test in super().split(X, y, groups):
  File "C:\Users\TP\anaconda3\lib\site-packages\sklearn\model_selection\_split.py", line 80, in split
    for test_index in self._iter_test_masks(X, y, groups):
  File "C:\Users\TP\anaconda3\lib\site-packages\sklearn\model_selection\_split.py", line 697, in _iter_test_masks
    test_folds = self._make_test_folds(X, y)
  File "C:\Users\TP\anaconda3\lib\site-packages\sklearn\model_selection\_split.py", line 649, in _make_test_folds
    raise ValueError(
ValueError: Supported target types are: ('binary', 'multiclass'). Got 'continuous' instead.

During handling of the above exception, another exception occurred:

Traceback (most recent call last):
  File "C:\Users\TP\anaconda3\lib\site-packages\joblib\parallel.py", line 827, in dispatch_one_batch
    tasks = self._ready_batches.get(block=False)
  File "C:\Users\TP\anaconda3\lib\queue.py", line 167, in get
    raise Empty
_queue.Empty

During handling of the above exception, another exception occurred:

Traceback (most recent call last):
  File "C:\Users\TP\AppData\Roaming\Python\Python38\site-packages\pycaret\internal\tabular.py", line 2215, in compare_models
    model, model_fit_time = create_model_supervised(**create_model_args)
  File "C:\Users\TP\AppData\Roaming\Python\Python38\site-packages\pycaret\internal\tabular.py", line 3171, in create_model_supervised
    scores = cross_validate(
  File "C:\Users\TP\anaconda3\lib\site-packages\sklearn\utils\validation.py", line 72, in inner_f
    return f(**kwargs)
  File "C:\Users\TP\anaconda3\lib\site-packages\sklearn\model_selection\_validation.py", line 242, in cross_validate
    scores = parallel(
  File "C:\Users\TP\anaconda3\lib\site-packages\joblib\parallel.py", line 1048, in __call__
    if self.dispatch_one_batch(iterator):
  File "C:\Users\TP\anaconda3\lib\site-packages\joblib\parallel.py", line 838, in dispatch_one_batch
    islice = list(itertools.islice(iterator, big_batch_size))
  File "C:\Users\TP\anaconda3\lib\site-packages\sklearn\model_selection\_validation.py", line 242, in <genexpr>
    scores = parallel(
  File "C:\Users\TP\anaconda3\lib\site-packages\sklearn\model_selection\_split.py", line 336, in split
    for train, test in super().split(X, y, groups):
  File "C:\Users\TP\anaconda3\lib\site-packages\sklearn\model_selection\_split.py", line 80, in split
    for test_index in self._iter_test_masks(X, y, groups):
  File "C:\Users\TP\anaconda3\lib\site-packages\sklearn\model_selection\_split.py", line 697, in _iter_test_masks
    test_folds = self._make_test_folds(X, y)
  File "C:\Users\TP\anaconda3\lib\site-packages\sklearn\model_selection\_split.py", line 649, in _make_test_folds
    raise ValueError(
ValueError: Supported target types are: ('binary', 'multiclass'). Got 'continuous' instead.

2022-02-13 01:27:16,621:INFO:Initializing Ada Boost Classifier
2022-02-13 01:27:16,621:INFO:Total runtime is 0.02195829550425212 minutes
2022-02-13 01:27:16,633:INFO:SubProcess create_model() called ==================================
2022-02-13 01:27:16,634:INFO:Initializing create_model()
2022-02-13 01:27:16,634:INFO:create_model(estimator=ada, fold=StratifiedKFold(n_splits=10, random_state=None, shuffle=False), round=4, cross_validation=True, predict=True, fit_kwargs={}, groups=None, refit=False, verbose=False, system=False, metrics=None, add_to_model_list=True, probability_threshold=None, display=<pycaret.internal.Display.Display object at 0x000001CFB6416DF0>, kwargs={})
2022-02-13 01:27:16,634:INFO:Checking exceptions
2022-02-13 01:27:16,634:INFO:Importing libraries
2022-02-13 01:27:16,634:INFO:Copying training dataset
2022-02-13 01:27:16,636:INFO:Defining folds
2022-02-13 01:27:16,637:INFO:Declaring metric variables
2022-02-13 01:27:16,646:INFO:Importing untrained model
2022-02-13 01:27:16,655:INFO:Ada Boost Classifier Imported succesfully
2022-02-13 01:27:16,678:INFO:Starting cross validation
2022-02-13 01:27:16,679:INFO:Cross validating with StratifiedKFold(n_splits=10, random_state=None, shuffle=False), n_jobs=-1
2022-02-13 01:27:16,682:WARNING:create_model() for ada raised an exception or returned all 0.0, trying without fit_kwargs:
2022-02-13 01:27:16,684:WARNING:Traceback (most recent call last):
  File "C:\Users\TP\anaconda3\lib\site-packages\joblib\parallel.py", line 827, in dispatch_one_batch
    tasks = self._ready_batches.get(block=False)
  File "C:\Users\TP\anaconda3\lib\queue.py", line 167, in get
    raise Empty
_queue.Empty

During handling of the above exception, another exception occurred:

Traceback (most recent call last):
  File "C:\Users\TP\AppData\Roaming\Python\Python38\site-packages\pycaret\internal\tabular.py", line 2206, in compare_models
    model, model_fit_time = create_model_supervised(**create_model_args)
  File "C:\Users\TP\AppData\Roaming\Python\Python38\site-packages\pycaret\internal\tabular.py", line 3171, in create_model_supervised
    scores = cross_validate(
  File "C:\Users\TP\anaconda3\lib\site-packages\sklearn\utils\validation.py", line 72, in inner_f
    return f(**kwargs)
  File "C:\Users\TP\anaconda3\lib\site-packages\sklearn\model_selection\_validation.py", line 242, in cross_validate
    scores = parallel(
  File "C:\Users\TP\anaconda3\lib\site-packages\joblib\parallel.py", line 1048, in __call__
    if self.dispatch_one_batch(iterator):
  File "C:\Users\TP\anaconda3\lib\site-packages\joblib\parallel.py", line 838, in dispatch_one_batch
    islice = list(itertools.islice(iterator, big_batch_size))
  File "C:\Users\TP\anaconda3\lib\site-packages\sklearn\model_selection\_validation.py", line 242, in <genexpr>
    scores = parallel(
  File "C:\Users\TP\anaconda3\lib\site-packages\sklearn\model_selection\_split.py", line 336, in split
    for train, test in super().split(X, y, groups):
  File "C:\Users\TP\anaconda3\lib\site-packages\sklearn\model_selection\_split.py", line 80, in split
    for test_index in self._iter_test_masks(X, y, groups):
  File "C:\Users\TP\anaconda3\lib\site-packages\sklearn\model_selection\_split.py", line 697, in _iter_test_masks
    test_folds = self._make_test_folds(X, y)
  File "C:\Users\TP\anaconda3\lib\site-packages\sklearn\model_selection\_split.py", line 649, in _make_test_folds
    raise ValueError(
ValueError: Supported target types are: ('binary', 'multiclass'). Got 'continuous' instead.

2022-02-13 01:27:16,684:INFO:Initializing create_model()
2022-02-13 01:27:16,684:INFO:create_model(estimator=ada, fold=StratifiedKFold(n_splits=10, random_state=None, shuffle=False), round=4, cross_validation=True, predict=True, fit_kwargs={}, groups=None, refit=False, verbose=False, system=False, metrics=None, add_to_model_list=True, probability_threshold=None, display=<pycaret.internal.Display.Display object at 0x000001CFB6416DF0>, kwargs={})
2022-02-13 01:27:16,684:INFO:Checking exceptions
2022-02-13 01:27:16,684:INFO:Importing libraries
2022-02-13 01:27:16,685:INFO:Copying training dataset
2022-02-13 01:27:16,687:INFO:Defining folds
2022-02-13 01:27:16,687:INFO:Declaring metric variables
2022-02-13 01:27:16,697:INFO:Importing untrained model
2022-02-13 01:27:16,706:INFO:Ada Boost Classifier Imported succesfully
2022-02-13 01:27:16,726:INFO:Starting cross validation
2022-02-13 01:27:16,727:INFO:Cross validating with StratifiedKFold(n_splits=10, random_state=None, shuffle=False), n_jobs=-1
2022-02-13 01:27:16,729:ERROR:create_model() for ada raised an exception or returned all 0.0:
2022-02-13 01:27:16,732:ERROR:Traceback (most recent call last):
  File "C:\Users\TP\anaconda3\lib\site-packages\joblib\parallel.py", line 827, in dispatch_one_batch
    tasks = self._ready_batches.get(block=False)
  File "C:\Users\TP\anaconda3\lib\queue.py", line 167, in get
    raise Empty
_queue.Empty

During handling of the above exception, another exception occurred:

Traceback (most recent call last):
  File "C:\Users\TP\AppData\Roaming\Python\Python38\site-packages\pycaret\internal\tabular.py", line 2206, in compare_models
    model, model_fit_time = create_model_supervised(**create_model_args)
  File "C:\Users\TP\AppData\Roaming\Python\Python38\site-packages\pycaret\internal\tabular.py", line 3171, in create_model_supervised
    scores = cross_validate(
  File "C:\Users\TP\anaconda3\lib\site-packages\sklearn\utils\validation.py", line 72, in inner_f
    return f(**kwargs)
  File "C:\Users\TP\anaconda3\lib\site-packages\sklearn\model_selection\_validation.py", line 242, in cross_validate
    scores = parallel(
  File "C:\Users\TP\anaconda3\lib\site-packages\joblib\parallel.py", line 1048, in __call__
    if self.dispatch_one_batch(iterator):
  File "C:\Users\TP\anaconda3\lib\site-packages\joblib\parallel.py", line 838, in dispatch_one_batch
    islice = list(itertools.islice(iterator, big_batch_size))
  File "C:\Users\TP\anaconda3\lib\site-packages\sklearn\model_selection\_validation.py", line 242, in <genexpr>
    scores = parallel(
  File "C:\Users\TP\anaconda3\lib\site-packages\sklearn\model_selection\_split.py", line 336, in split
    for train, test in super().split(X, y, groups):
  File "C:\Users\TP\anaconda3\lib\site-packages\sklearn\model_selection\_split.py", line 80, in split
    for test_index in self._iter_test_masks(X, y, groups):
  File "C:\Users\TP\anaconda3\lib\site-packages\sklearn\model_selection\_split.py", line 697, in _iter_test_masks
    test_folds = self._make_test_folds(X, y)
  File "C:\Users\TP\anaconda3\lib\site-packages\sklearn\model_selection\_split.py", line 649, in _make_test_folds
    raise ValueError(
ValueError: Supported target types are: ('binary', 'multiclass'). Got 'continuous' instead.

During handling of the above exception, another exception occurred:

Traceback (most recent call last):
  File "C:\Users\TP\anaconda3\lib\site-packages\joblib\parallel.py", line 827, in dispatch_one_batch
    tasks = self._ready_batches.get(block=False)
  File "C:\Users\TP\anaconda3\lib\queue.py", line 167, in get
    raise Empty
_queue.Empty

During handling of the above exception, another exception occurred:

Traceback (most recent call last):
  File "C:\Users\TP\AppData\Roaming\Python\Python38\site-packages\pycaret\internal\tabular.py", line 2215, in compare_models
    model, model_fit_time = create_model_supervised(**create_model_args)
  File "C:\Users\TP\AppData\Roaming\Python\Python38\site-packages\pycaret\internal\tabular.py", line 3171, in create_model_supervised
    scores = cross_validate(
  File "C:\Users\TP\anaconda3\lib\site-packages\sklearn\utils\validation.py", line 72, in inner_f
    return f(**kwargs)
  File "C:\Users\TP\anaconda3\lib\site-packages\sklearn\model_selection\_validation.py", line 242, in cross_validate
    scores = parallel(
  File "C:\Users\TP\anaconda3\lib\site-packages\joblib\parallel.py", line 1048, in __call__
    if self.dispatch_one_batch(iterator):
  File "C:\Users\TP\anaconda3\lib\site-packages\joblib\parallel.py", line 838, in dispatch_one_batch
    islice = list(itertools.islice(iterator, big_batch_size))
  File "C:\Users\TP\anaconda3\lib\site-packages\sklearn\model_selection\_validation.py", line 242, in <genexpr>
    scores = parallel(
  File "C:\Users\TP\anaconda3\lib\site-packages\sklearn\model_selection\_split.py", line 336, in split
    for train, test in super().split(X, y, groups):
  File "C:\Users\TP\anaconda3\lib\site-packages\sklearn\model_selection\_split.py", line 80, in split
    for test_index in self._iter_test_masks(X, y, groups):
  File "C:\Users\TP\anaconda3\lib\site-packages\sklearn\model_selection\_split.py", line 697, in _iter_test_masks
    test_folds = self._make_test_folds(X, y)
  File "C:\Users\TP\anaconda3\lib\site-packages\sklearn\model_selection\_split.py", line 649, in _make_test_folds
    raise ValueError(
ValueError: Supported target types are: ('binary', 'multiclass'). Got 'continuous' instead.

2022-02-13 01:27:16,733:INFO:Initializing Gradient Boosting Classifier
2022-02-13 01:27:16,733:INFO:Total runtime is 0.023824354012807213 minutes
2022-02-13 01:27:16,743:INFO:SubProcess create_model() called ==================================
2022-02-13 01:27:16,743:INFO:Initializing create_model()
2022-02-13 01:27:16,743:INFO:create_model(estimator=gbc, fold=StratifiedKFold(n_splits=10, random_state=None, shuffle=False), round=4, cross_validation=True, predict=True, fit_kwargs={}, groups=None, refit=False, verbose=False, system=False, metrics=None, add_to_model_list=True, probability_threshold=None, display=<pycaret.internal.Display.Display object at 0x000001CFB6416DF0>, kwargs={})
2022-02-13 01:27:16,743:INFO:Checking exceptions
2022-02-13 01:27:16,743:INFO:Importing libraries
2022-02-13 01:27:16,743:INFO:Copying training dataset
2022-02-13 01:27:16,745:INFO:Defining folds
2022-02-13 01:27:16,745:INFO:Declaring metric variables
2022-02-13 01:27:16,754:INFO:Importing untrained model
2022-02-13 01:27:16,764:INFO:Gradient Boosting Classifier Imported succesfully
2022-02-13 01:27:16,783:INFO:Starting cross validation
2022-02-13 01:27:16,784:INFO:Cross validating with StratifiedKFold(n_splits=10, random_state=None, shuffle=False), n_jobs=-1
2022-02-13 01:27:16,786:WARNING:create_model() for gbc raised an exception or returned all 0.0, trying without fit_kwargs:
2022-02-13 01:27:16,787:WARNING:Traceback (most recent call last):
  File "C:\Users\TP\anaconda3\lib\site-packages\joblib\parallel.py", line 827, in dispatch_one_batch
    tasks = self._ready_batches.get(block=False)
  File "C:\Users\TP\anaconda3\lib\queue.py", line 167, in get
    raise Empty
_queue.Empty

During handling of the above exception, another exception occurred:

Traceback (most recent call last):
  File "C:\Users\TP\AppData\Roaming\Python\Python38\site-packages\pycaret\internal\tabular.py", line 2206, in compare_models
    model, model_fit_time = create_model_supervised(**create_model_args)
  File "C:\Users\TP\AppData\Roaming\Python\Python38\site-packages\pycaret\internal\tabular.py", line 3171, in create_model_supervised
    scores = cross_validate(
  File "C:\Users\TP\anaconda3\lib\site-packages\sklearn\utils\validation.py", line 72, in inner_f
    return f(**kwargs)
  File "C:\Users\TP\anaconda3\lib\site-packages\sklearn\model_selection\_validation.py", line 242, in cross_validate
    scores = parallel(
  File "C:\Users\TP\anaconda3\lib\site-packages\joblib\parallel.py", line 1048, in __call__
    if self.dispatch_one_batch(iterator):
  File "C:\Users\TP\anaconda3\lib\site-packages\joblib\parallel.py", line 838, in dispatch_one_batch
    islice = list(itertools.islice(iterator, big_batch_size))
  File "C:\Users\TP\anaconda3\lib\site-packages\sklearn\model_selection\_validation.py", line 242, in <genexpr>
    scores = parallel(
  File "C:\Users\TP\anaconda3\lib\site-packages\sklearn\model_selection\_split.py", line 336, in split
    for train, test in super().split(X, y, groups):
  File "C:\Users\TP\anaconda3\lib\site-packages\sklearn\model_selection\_split.py", line 80, in split
    for test_index in self._iter_test_masks(X, y, groups):
  File "C:\Users\TP\anaconda3\lib\site-packages\sklearn\model_selection\_split.py", line 697, in _iter_test_masks
    test_folds = self._make_test_folds(X, y)
  File "C:\Users\TP\anaconda3\lib\site-packages\sklearn\model_selection\_split.py", line 649, in _make_test_folds
    raise ValueError(
ValueError: Supported target types are: ('binary', 'multiclass'). Got 'continuous' instead.

2022-02-13 01:27:16,787:INFO:Initializing create_model()
2022-02-13 01:27:16,787:INFO:create_model(estimator=gbc, fold=StratifiedKFold(n_splits=10, random_state=None, shuffle=False), round=4, cross_validation=True, predict=True, fit_kwargs={}, groups=None, refit=False, verbose=False, system=False, metrics=None, add_to_model_list=True, probability_threshold=None, display=<pycaret.internal.Display.Display object at 0x000001CFB6416DF0>, kwargs={})
2022-02-13 01:27:16,787:INFO:Checking exceptions
2022-02-13 01:27:16,787:INFO:Importing libraries
2022-02-13 01:27:16,787:INFO:Copying training dataset
2022-02-13 01:27:16,789:INFO:Defining folds
2022-02-13 01:27:16,789:INFO:Declaring metric variables
2022-02-13 01:27:16,798:INFO:Importing untrained model
2022-02-13 01:27:16,807:INFO:Gradient Boosting Classifier Imported succesfully
2022-02-13 01:27:16,827:INFO:Starting cross validation
2022-02-13 01:27:16,827:INFO:Cross validating with StratifiedKFold(n_splits=10, random_state=None, shuffle=False), n_jobs=-1
2022-02-13 01:27:16,829:ERROR:create_model() for gbc raised an exception or returned all 0.0:
2022-02-13 01:27:16,832:ERROR:Traceback (most recent call last):
  File "C:\Users\TP\anaconda3\lib\site-packages\joblib\parallel.py", line 827, in dispatch_one_batch
    tasks = self._ready_batches.get(block=False)
  File "C:\Users\TP\anaconda3\lib\queue.py", line 167, in get
    raise Empty
_queue.Empty

During handling of the above exception, another exception occurred:

Traceback (most recent call last):
  File "C:\Users\TP\AppData\Roaming\Python\Python38\site-packages\pycaret\internal\tabular.py", line 2206, in compare_models
    model, model_fit_time = create_model_supervised(**create_model_args)
  File "C:\Users\TP\AppData\Roaming\Python\Python38\site-packages\pycaret\internal\tabular.py", line 3171, in create_model_supervised
    scores = cross_validate(
  File "C:\Users\TP\anaconda3\lib\site-packages\sklearn\utils\validation.py", line 72, in inner_f
    return f(**kwargs)
  File "C:\Users\TP\anaconda3\lib\site-packages\sklearn\model_selection\_validation.py", line 242, in cross_validate
    scores = parallel(
  File "C:\Users\TP\anaconda3\lib\site-packages\joblib\parallel.py", line 1048, in __call__
    if self.dispatch_one_batch(iterator):
  File "C:\Users\TP\anaconda3\lib\site-packages\joblib\parallel.py", line 838, in dispatch_one_batch
    islice = list(itertools.islice(iterator, big_batch_size))
  File "C:\Users\TP\anaconda3\lib\site-packages\sklearn\model_selection\_validation.py", line 242, in <genexpr>
    scores = parallel(
  File "C:\Users\TP\anaconda3\lib\site-packages\sklearn\model_selection\_split.py", line 336, in split
    for train, test in super().split(X, y, groups):
  File "C:\Users\TP\anaconda3\lib\site-packages\sklearn\model_selection\_split.py", line 80, in split
    for test_index in self._iter_test_masks(X, y, groups):
  File "C:\Users\TP\anaconda3\lib\site-packages\sklearn\model_selection\_split.py", line 697, in _iter_test_masks
    test_folds = self._make_test_folds(X, y)
  File "C:\Users\TP\anaconda3\lib\site-packages\sklearn\model_selection\_split.py", line 649, in _make_test_folds
    raise ValueError(
ValueError: Supported target types are: ('binary', 'multiclass'). Got 'continuous' instead.

During handling of the above exception, another exception occurred:

Traceback (most recent call last):
  File "C:\Users\TP\anaconda3\lib\site-packages\joblib\parallel.py", line 827, in dispatch_one_batch
    tasks = self._ready_batches.get(block=False)
  File "C:\Users\TP\anaconda3\lib\queue.py", line 167, in get
    raise Empty
_queue.Empty

During handling of the above exception, another exception occurred:

Traceback (most recent call last):
  File "C:\Users\TP\AppData\Roaming\Python\Python38\site-packages\pycaret\internal\tabular.py", line 2215, in compare_models
    model, model_fit_time = create_model_supervised(**create_model_args)
  File "C:\Users\TP\AppData\Roaming\Python\Python38\site-packages\pycaret\internal\tabular.py", line 3171, in create_model_supervised
    scores = cross_validate(
  File "C:\Users\TP\anaconda3\lib\site-packages\sklearn\utils\validation.py", line 72, in inner_f
    return f(**kwargs)
  File "C:\Users\TP\anaconda3\lib\site-packages\sklearn\model_selection\_validation.py", line 242, in cross_validate
    scores = parallel(
  File "C:\Users\TP\anaconda3\lib\site-packages\joblib\parallel.py", line 1048, in __call__
    if self.dispatch_one_batch(iterator):
  File "C:\Users\TP\anaconda3\lib\site-packages\joblib\parallel.py", line 838, in dispatch_one_batch
    islice = list(itertools.islice(iterator, big_batch_size))
  File "C:\Users\TP\anaconda3\lib\site-packages\sklearn\model_selection\_validation.py", line 242, in <genexpr>
    scores = parallel(
  File "C:\Users\TP\anaconda3\lib\site-packages\sklearn\model_selection\_split.py", line 336, in split
    for train, test in super().split(X, y, groups):
  File "C:\Users\TP\anaconda3\lib\site-packages\sklearn\model_selection\_split.py", line 80, in split
    for test_index in self._iter_test_masks(X, y, groups):
  File "C:\Users\TP\anaconda3\lib\site-packages\sklearn\model_selection\_split.py", line 697, in _iter_test_masks
    test_folds = self._make_test_folds(X, y)
  File "C:\Users\TP\anaconda3\lib\site-packages\sklearn\model_selection\_split.py", line 649, in _make_test_folds
    raise ValueError(
ValueError: Supported target types are: ('binary', 'multiclass'). Got 'continuous' instead.

2022-02-13 01:27:16,833:INFO:Initializing Linear Discriminant Analysis
2022-02-13 01:27:16,833:INFO:Total runtime is 0.025495763619740805 minutes
2022-02-13 01:27:16,842:INFO:SubProcess create_model() called ==================================
2022-02-13 01:27:16,843:INFO:Initializing create_model()
2022-02-13 01:27:16,843:INFO:create_model(estimator=lda, fold=StratifiedKFold(n_splits=10, random_state=None, shuffle=False), round=4, cross_validation=True, predict=True, fit_kwargs={}, groups=None, refit=False, verbose=False, system=False, metrics=None, add_to_model_list=True, probability_threshold=None, display=<pycaret.internal.Display.Display object at 0x000001CFB6416DF0>, kwargs={})
2022-02-13 01:27:16,843:INFO:Checking exceptions
2022-02-13 01:27:16,843:INFO:Importing libraries
2022-02-13 01:27:16,843:INFO:Copying training dataset
2022-02-13 01:27:16,846:INFO:Defining folds
2022-02-13 01:27:16,846:INFO:Declaring metric variables
2022-02-13 01:27:16,854:INFO:Importing untrained model
2022-02-13 01:27:16,863:INFO:Linear Discriminant Analysis Imported succesfully
2022-02-13 01:27:16,884:INFO:Starting cross validation
2022-02-13 01:27:16,885:INFO:Cross validating with StratifiedKFold(n_splits=10, random_state=None, shuffle=False), n_jobs=-1
2022-02-13 01:27:16,886:WARNING:create_model() for lda raised an exception or returned all 0.0, trying without fit_kwargs:
2022-02-13 01:27:16,888:WARNING:Traceback (most recent call last):
  File "C:\Users\TP\anaconda3\lib\site-packages\joblib\parallel.py", line 827, in dispatch_one_batch
    tasks = self._ready_batches.get(block=False)
  File "C:\Users\TP\anaconda3\lib\queue.py", line 167, in get
    raise Empty
_queue.Empty

During handling of the above exception, another exception occurred:

Traceback (most recent call last):
  File "C:\Users\TP\AppData\Roaming\Python\Python38\site-packages\pycaret\internal\tabular.py", line 2206, in compare_models
    model, model_fit_time = create_model_supervised(**create_model_args)
  File "C:\Users\TP\AppData\Roaming\Python\Python38\site-packages\pycaret\internal\tabular.py", line 3171, in create_model_supervised
    scores = cross_validate(
  File "C:\Users\TP\anaconda3\lib\site-packages\sklearn\utils\validation.py", line 72, in inner_f
    return f(**kwargs)
  File "C:\Users\TP\anaconda3\lib\site-packages\sklearn\model_selection\_validation.py", line 242, in cross_validate
    scores = parallel(
  File "C:\Users\TP\anaconda3\lib\site-packages\joblib\parallel.py", line 1048, in __call__
    if self.dispatch_one_batch(iterator):
  File "C:\Users\TP\anaconda3\lib\site-packages\joblib\parallel.py", line 838, in dispatch_one_batch
    islice = list(itertools.islice(iterator, big_batch_size))
  File "C:\Users\TP\anaconda3\lib\site-packages\sklearn\model_selection\_validation.py", line 242, in <genexpr>
    scores = parallel(
  File "C:\Users\TP\anaconda3\lib\site-packages\sklearn\model_selection\_split.py", line 336, in split
    for train, test in super().split(X, y, groups):
  File "C:\Users\TP\anaconda3\lib\site-packages\sklearn\model_selection\_split.py", line 80, in split
    for test_index in self._iter_test_masks(X, y, groups):
  File "C:\Users\TP\anaconda3\lib\site-packages\sklearn\model_selection\_split.py", line 697, in _iter_test_masks
    test_folds = self._make_test_folds(X, y)
  File "C:\Users\TP\anaconda3\lib\site-packages\sklearn\model_selection\_split.py", line 649, in _make_test_folds
    raise ValueError(
ValueError: Supported target types are: ('binary', 'multiclass'). Got 'continuous' instead.

2022-02-13 01:27:16,888:INFO:Initializing create_model()
2022-02-13 01:27:16,888:INFO:create_model(estimator=lda, fold=StratifiedKFold(n_splits=10, random_state=None, shuffle=False), round=4, cross_validation=True, predict=True, fit_kwargs={}, groups=None, refit=False, verbose=False, system=False, metrics=None, add_to_model_list=True, probability_threshold=None, display=<pycaret.internal.Display.Display object at 0x000001CFB6416DF0>, kwargs={})
2022-02-13 01:27:16,888:INFO:Checking exceptions
2022-02-13 01:27:16,888:INFO:Importing libraries
2022-02-13 01:27:16,888:INFO:Copying training dataset
2022-02-13 01:27:16,891:INFO:Defining folds
2022-02-13 01:27:16,891:INFO:Declaring metric variables
2022-02-13 01:27:16,900:INFO:Importing untrained model
2022-02-13 01:27:16,909:INFO:Linear Discriminant Analysis Imported succesfully
2022-02-13 01:27:16,928:INFO:Starting cross validation
2022-02-13 01:27:16,928:INFO:Cross validating with StratifiedKFold(n_splits=10, random_state=None, shuffle=False), n_jobs=-1
2022-02-13 01:27:16,931:ERROR:create_model() for lda raised an exception or returned all 0.0:
2022-02-13 01:27:16,933:ERROR:Traceback (most recent call last):
  File "C:\Users\TP\anaconda3\lib\site-packages\joblib\parallel.py", line 827, in dispatch_one_batch
    tasks = self._ready_batches.get(block=False)
  File "C:\Users\TP\anaconda3\lib\queue.py", line 167, in get
    raise Empty
_queue.Empty

During handling of the above exception, another exception occurred:

Traceback (most recent call last):
  File "C:\Users\TP\AppData\Roaming\Python\Python38\site-packages\pycaret\internal\tabular.py", line 2206, in compare_models
    model, model_fit_time = create_model_supervised(**create_model_args)
  File "C:\Users\TP\AppData\Roaming\Python\Python38\site-packages\pycaret\internal\tabular.py", line 3171, in create_model_supervised
    scores = cross_validate(
  File "C:\Users\TP\anaconda3\lib\site-packages\sklearn\utils\validation.py", line 72, in inner_f
    return f(**kwargs)
  File "C:\Users\TP\anaconda3\lib\site-packages\sklearn\model_selection\_validation.py", line 242, in cross_validate
    scores = parallel(
  File "C:\Users\TP\anaconda3\lib\site-packages\joblib\parallel.py", line 1048, in __call__
    if self.dispatch_one_batch(iterator):
  File "C:\Users\TP\anaconda3\lib\site-packages\joblib\parallel.py", line 838, in dispatch_one_batch
    islice = list(itertools.islice(iterator, big_batch_size))
  File "C:\Users\TP\anaconda3\lib\site-packages\sklearn\model_selection\_validation.py", line 242, in <genexpr>
    scores = parallel(
  File "C:\Users\TP\anaconda3\lib\site-packages\sklearn\model_selection\_split.py", line 336, in split
    for train, test in super().split(X, y, groups):
  File "C:\Users\TP\anaconda3\lib\site-packages\sklearn\model_selection\_split.py", line 80, in split
    for test_index in self._iter_test_masks(X, y, groups):
  File "C:\Users\TP\anaconda3\lib\site-packages\sklearn\model_selection\_split.py", line 697, in _iter_test_masks
    test_folds = self._make_test_folds(X, y)
  File "C:\Users\TP\anaconda3\lib\site-packages\sklearn\model_selection\_split.py", line 649, in _make_test_folds
    raise ValueError(
ValueError: Supported target types are: ('binary', 'multiclass'). Got 'continuous' instead.

During handling of the above exception, another exception occurred:

Traceback (most recent call last):
  File "C:\Users\TP\anaconda3\lib\site-packages\joblib\parallel.py", line 827, in dispatch_one_batch
    tasks = self._ready_batches.get(block=False)
  File "C:\Users\TP\anaconda3\lib\queue.py", line 167, in get
    raise Empty
_queue.Empty

During handling of the above exception, another exception occurred:

Traceback (most recent call last):
  File "C:\Users\TP\AppData\Roaming\Python\Python38\site-packages\pycaret\internal\tabular.py", line 2215, in compare_models
    model, model_fit_time = create_model_supervised(**create_model_args)
  File "C:\Users\TP\AppData\Roaming\Python\Python38\site-packages\pycaret\internal\tabular.py", line 3171, in create_model_supervised
    scores = cross_validate(
  File "C:\Users\TP\anaconda3\lib\site-packages\sklearn\utils\validation.py", line 72, in inner_f
    return f(**kwargs)
  File "C:\Users\TP\anaconda3\lib\site-packages\sklearn\model_selection\_validation.py", line 242, in cross_validate
    scores = parallel(
  File "C:\Users\TP\anaconda3\lib\site-packages\joblib\parallel.py", line 1048, in __call__
    if self.dispatch_one_batch(iterator):
  File "C:\Users\TP\anaconda3\lib\site-packages\joblib\parallel.py", line 838, in dispatch_one_batch
    islice = list(itertools.islice(iterator, big_batch_size))
  File "C:\Users\TP\anaconda3\lib\site-packages\sklearn\model_selection\_validation.py", line 242, in <genexpr>
    scores = parallel(
  File "C:\Users\TP\anaconda3\lib\site-packages\sklearn\model_selection\_split.py", line 336, in split
    for train, test in super().split(X, y, groups):
  File "C:\Users\TP\anaconda3\lib\site-packages\sklearn\model_selection\_split.py", line 80, in split
    for test_index in self._iter_test_masks(X, y, groups):
  File "C:\Users\TP\anaconda3\lib\site-packages\sklearn\model_selection\_split.py", line 697, in _iter_test_masks
    test_folds = self._make_test_folds(X, y)
  File "C:\Users\TP\anaconda3\lib\site-packages\sklearn\model_selection\_split.py", line 649, in _make_test_folds
    raise ValueError(
ValueError: Supported target types are: ('binary', 'multiclass'). Got 'continuous' instead.

2022-02-13 01:27:16,934:INFO:Initializing Extra Trees Classifier
2022-02-13 01:27:16,934:INFO:Total runtime is 0.027174512545267742 minutes
2022-02-13 01:27:16,943:INFO:SubProcess create_model() called ==================================
2022-02-13 01:27:16,944:INFO:Initializing create_model()
2022-02-13 01:27:16,944:INFO:create_model(estimator=et, fold=StratifiedKFold(n_splits=10, random_state=None, shuffle=False), round=4, cross_validation=True, predict=True, fit_kwargs={}, groups=None, refit=False, verbose=False, system=False, metrics=None, add_to_model_list=True, probability_threshold=None, display=<pycaret.internal.Display.Display object at 0x000001CFB6416DF0>, kwargs={})
2022-02-13 01:27:16,944:INFO:Checking exceptions
2022-02-13 01:27:16,944:INFO:Importing libraries
2022-02-13 01:27:16,944:INFO:Copying training dataset
2022-02-13 01:27:16,947:INFO:Defining folds
2022-02-13 01:27:16,947:INFO:Declaring metric variables
2022-02-13 01:27:16,956:INFO:Importing untrained model
2022-02-13 01:27:16,974:INFO:Extra Trees Classifier Imported succesfully
2022-02-13 01:27:16,994:INFO:Starting cross validation
2022-02-13 01:27:16,995:INFO:Cross validating with StratifiedKFold(n_splits=10, random_state=None, shuffle=False), n_jobs=-1
2022-02-13 01:27:16,997:WARNING:create_model() for et raised an exception or returned all 0.0, trying without fit_kwargs:
2022-02-13 01:27:16,999:WARNING:Traceback (most recent call last):
  File "C:\Users\TP\anaconda3\lib\site-packages\joblib\parallel.py", line 827, in dispatch_one_batch
    tasks = self._ready_batches.get(block=False)
  File "C:\Users\TP\anaconda3\lib\queue.py", line 167, in get
    raise Empty
_queue.Empty

During handling of the above exception, another exception occurred:

Traceback (most recent call last):
  File "C:\Users\TP\AppData\Roaming\Python\Python38\site-packages\pycaret\internal\tabular.py", line 2206, in compare_models
    model, model_fit_time = create_model_supervised(**create_model_args)
  File "C:\Users\TP\AppData\Roaming\Python\Python38\site-packages\pycaret\internal\tabular.py", line 3171, in create_model_supervised
    scores = cross_validate(
  File "C:\Users\TP\anaconda3\lib\site-packages\sklearn\utils\validation.py", line 72, in inner_f
    return f(**kwargs)
  File "C:\Users\TP\anaconda3\lib\site-packages\sklearn\model_selection\_validation.py", line 242, in cross_validate
    scores = parallel(
  File "C:\Users\TP\anaconda3\lib\site-packages\joblib\parallel.py", line 1048, in __call__
    if self.dispatch_one_batch(iterator):
  File "C:\Users\TP\anaconda3\lib\site-packages\joblib\parallel.py", line 838, in dispatch_one_batch
    islice = list(itertools.islice(iterator, big_batch_size))
  File "C:\Users\TP\anaconda3\lib\site-packages\sklearn\model_selection\_validation.py", line 242, in <genexpr>
    scores = parallel(
  File "C:\Users\TP\anaconda3\lib\site-packages\sklearn\model_selection\_split.py", line 336, in split
    for train, test in super().split(X, y, groups):
  File "C:\Users\TP\anaconda3\lib\site-packages\sklearn\model_selection\_split.py", line 80, in split
    for test_index in self._iter_test_masks(X, y, groups):
  File "C:\Users\TP\anaconda3\lib\site-packages\sklearn\model_selection\_split.py", line 697, in _iter_test_masks
    test_folds = self._make_test_folds(X, y)
  File "C:\Users\TP\anaconda3\lib\site-packages\sklearn\model_selection\_split.py", line 649, in _make_test_folds
    raise ValueError(
ValueError: Supported target types are: ('binary', 'multiclass'). Got 'continuous' instead.

2022-02-13 01:27:16,999:INFO:Initializing create_model()
2022-02-13 01:27:16,999:INFO:create_model(estimator=et, fold=StratifiedKFold(n_splits=10, random_state=None, shuffle=False), round=4, cross_validation=True, predict=True, fit_kwargs={}, groups=None, refit=False, verbose=False, system=False, metrics=None, add_to_model_list=True, probability_threshold=None, display=<pycaret.internal.Display.Display object at 0x000001CFB6416DF0>, kwargs={})
2022-02-13 01:27:17,000:INFO:Checking exceptions
2022-02-13 01:27:17,000:INFO:Importing libraries
2022-02-13 01:27:17,000:INFO:Copying training dataset
2022-02-13 01:27:17,001:INFO:Defining folds
2022-02-13 01:27:17,002:INFO:Declaring metric variables
2022-02-13 01:27:17,011:INFO:Importing untrained model
2022-02-13 01:27:17,020:INFO:Extra Trees Classifier Imported succesfully
2022-02-13 01:27:17,038:INFO:Starting cross validation
2022-02-13 01:27:17,038:INFO:Cross validating with StratifiedKFold(n_splits=10, random_state=None, shuffle=False), n_jobs=-1
2022-02-13 01:27:17,040:ERROR:create_model() for et raised an exception or returned all 0.0:
2022-02-13 01:27:17,043:ERROR:Traceback (most recent call last):
  File "C:\Users\TP\anaconda3\lib\site-packages\joblib\parallel.py", line 827, in dispatch_one_batch
    tasks = self._ready_batches.get(block=False)
  File "C:\Users\TP\anaconda3\lib\queue.py", line 167, in get
    raise Empty
_queue.Empty

During handling of the above exception, another exception occurred:

Traceback (most recent call last):
  File "C:\Users\TP\AppData\Roaming\Python\Python38\site-packages\pycaret\internal\tabular.py", line 2206, in compare_models
    model, model_fit_time = create_model_supervised(**create_model_args)
  File "C:\Users\TP\AppData\Roaming\Python\Python38\site-packages\pycaret\internal\tabular.py", line 3171, in create_model_supervised
    scores = cross_validate(
  File "C:\Users\TP\anaconda3\lib\site-packages\sklearn\utils\validation.py", line 72, in inner_f
    return f(**kwargs)
  File "C:\Users\TP\anaconda3\lib\site-packages\sklearn\model_selection\_validation.py", line 242, in cross_validate
    scores = parallel(
  File "C:\Users\TP\anaconda3\lib\site-packages\joblib\parallel.py", line 1048, in __call__
    if self.dispatch_one_batch(iterator):
  File "C:\Users\TP\anaconda3\lib\site-packages\joblib\parallel.py", line 838, in dispatch_one_batch
    islice = list(itertools.islice(iterator, big_batch_size))
  File "C:\Users\TP\anaconda3\lib\site-packages\sklearn\model_selection\_validation.py", line 242, in <genexpr>
    scores = parallel(
  File "C:\Users\TP\anaconda3\lib\site-packages\sklearn\model_selection\_split.py", line 336, in split
    for train, test in super().split(X, y, groups):
  File "C:\Users\TP\anaconda3\lib\site-packages\sklearn\model_selection\_split.py", line 80, in split
    for test_index in self._iter_test_masks(X, y, groups):
  File "C:\Users\TP\anaconda3\lib\site-packages\sklearn\model_selection\_split.py", line 697, in _iter_test_masks
    test_folds = self._make_test_folds(X, y)
  File "C:\Users\TP\anaconda3\lib\site-packages\sklearn\model_selection\_split.py", line 649, in _make_test_folds
    raise ValueError(
ValueError: Supported target types are: ('binary', 'multiclass'). Got 'continuous' instead.

During handling of the above exception, another exception occurred:

Traceback (most recent call last):
  File "C:\Users\TP\anaconda3\lib\site-packages\joblib\parallel.py", line 827, in dispatch_one_batch
    tasks = self._ready_batches.get(block=False)
  File "C:\Users\TP\anaconda3\lib\queue.py", line 167, in get
    raise Empty
_queue.Empty

During handling of the above exception, another exception occurred:

Traceback (most recent call last):
  File "C:\Users\TP\AppData\Roaming\Python\Python38\site-packages\pycaret\internal\tabular.py", line 2215, in compare_models
    model, model_fit_time = create_model_supervised(**create_model_args)
  File "C:\Users\TP\AppData\Roaming\Python\Python38\site-packages\pycaret\internal\tabular.py", line 3171, in create_model_supervised
    scores = cross_validate(
  File "C:\Users\TP\anaconda3\lib\site-packages\sklearn\utils\validation.py", line 72, in inner_f
    return f(**kwargs)
  File "C:\Users\TP\anaconda3\lib\site-packages\sklearn\model_selection\_validation.py", line 242, in cross_validate
    scores = parallel(
  File "C:\Users\TP\anaconda3\lib\site-packages\joblib\parallel.py", line 1048, in __call__
    if self.dispatch_one_batch(iterator):
  File "C:\Users\TP\anaconda3\lib\site-packages\joblib\parallel.py", line 838, in dispatch_one_batch
    islice = list(itertools.islice(iterator, big_batch_size))
  File "C:\Users\TP\anaconda3\lib\site-packages\sklearn\model_selection\_validation.py", line 242, in <genexpr>
    scores = parallel(
  File "C:\Users\TP\anaconda3\lib\site-packages\sklearn\model_selection\_split.py", line 336, in split
    for train, test in super().split(X, y, groups):
  File "C:\Users\TP\anaconda3\lib\site-packages\sklearn\model_selection\_split.py", line 80, in split
    for test_index in self._iter_test_masks(X, y, groups):
  File "C:\Users\TP\anaconda3\lib\site-packages\sklearn\model_selection\_split.py", line 697, in _iter_test_masks
    test_folds = self._make_test_folds(X, y)
  File "C:\Users\TP\anaconda3\lib\site-packages\sklearn\model_selection\_split.py", line 649, in _make_test_folds
    raise ValueError(
ValueError: Supported target types are: ('binary', 'multiclass'). Got 'continuous' instead.

2022-02-13 01:27:17,044:INFO:Initializing Light Gradient Boosting Machine
2022-02-13 01:27:17,044:INFO:Total runtime is 0.029002984364827476 minutes
2022-02-13 01:27:17,053:INFO:SubProcess create_model() called ==================================
2022-02-13 01:27:17,054:INFO:Initializing create_model()
2022-02-13 01:27:17,054:INFO:create_model(estimator=lightgbm, fold=StratifiedKFold(n_splits=10, random_state=None, shuffle=False), round=4, cross_validation=True, predict=True, fit_kwargs={}, groups=None, refit=False, verbose=False, system=False, metrics=None, add_to_model_list=True, probability_threshold=None, display=<pycaret.internal.Display.Display object at 0x000001CFB6416DF0>, kwargs={})
2022-02-13 01:27:17,054:INFO:Checking exceptions
2022-02-13 01:27:17,054:INFO:Importing libraries
2022-02-13 01:27:17,054:INFO:Copying training dataset
2022-02-13 01:27:17,056:INFO:Defining folds
2022-02-13 01:27:17,056:INFO:Declaring metric variables
2022-02-13 01:27:17,065:INFO:Importing untrained model
2022-02-13 01:27:17,075:INFO:Light Gradient Boosting Machine Imported succesfully
2022-02-13 01:27:17,093:INFO:Starting cross validation
2022-02-13 01:27:17,094:INFO:Cross validating with StratifiedKFold(n_splits=10, random_state=None, shuffle=False), n_jobs=-1
2022-02-13 01:27:17,096:WARNING:create_model() for lightgbm raised an exception or returned all 0.0, trying without fit_kwargs:
2022-02-13 01:27:17,097:WARNING:Traceback (most recent call last):
  File "C:\Users\TP\anaconda3\lib\site-packages\joblib\parallel.py", line 827, in dispatch_one_batch
    tasks = self._ready_batches.get(block=False)
  File "C:\Users\TP\anaconda3\lib\queue.py", line 167, in get
    raise Empty
_queue.Empty

During handling of the above exception, another exception occurred:

Traceback (most recent call last):
  File "C:\Users\TP\AppData\Roaming\Python\Python38\site-packages\pycaret\internal\tabular.py", line 2206, in compare_models
    model, model_fit_time = create_model_supervised(**create_model_args)
  File "C:\Users\TP\AppData\Roaming\Python\Python38\site-packages\pycaret\internal\tabular.py", line 3171, in create_model_supervised
    scores = cross_validate(
  File "C:\Users\TP\anaconda3\lib\site-packages\sklearn\utils\validation.py", line 72, in inner_f
    return f(**kwargs)
  File "C:\Users\TP\anaconda3\lib\site-packages\sklearn\model_selection\_validation.py", line 242, in cross_validate
    scores = parallel(
  File "C:\Users\TP\anaconda3\lib\site-packages\joblib\parallel.py", line 1048, in __call__
    if self.dispatch_one_batch(iterator):
  File "C:\Users\TP\anaconda3\lib\site-packages\joblib\parallel.py", line 838, in dispatch_one_batch
    islice = list(itertools.islice(iterator, big_batch_size))
  File "C:\Users\TP\anaconda3\lib\site-packages\sklearn\model_selection\_validation.py", line 242, in <genexpr>
    scores = parallel(
  File "C:\Users\TP\anaconda3\lib\site-packages\sklearn\model_selection\_split.py", line 336, in split
    for train, test in super().split(X, y, groups):
  File "C:\Users\TP\anaconda3\lib\site-packages\sklearn\model_selection\_split.py", line 80, in split
    for test_index in self._iter_test_masks(X, y, groups):
  File "C:\Users\TP\anaconda3\lib\site-packages\sklearn\model_selection\_split.py", line 697, in _iter_test_masks
    test_folds = self._make_test_folds(X, y)
  File "C:\Users\TP\anaconda3\lib\site-packages\sklearn\model_selection\_split.py", line 649, in _make_test_folds
    raise ValueError(
ValueError: Supported target types are: ('binary', 'multiclass'). Got 'continuous' instead.

2022-02-13 01:27:17,098:INFO:Initializing create_model()
2022-02-13 01:27:17,098:INFO:create_model(estimator=lightgbm, fold=StratifiedKFold(n_splits=10, random_state=None, shuffle=False), round=4, cross_validation=True, predict=True, fit_kwargs={}, groups=None, refit=False, verbose=False, system=False, metrics=None, add_to_model_list=True, probability_threshold=None, display=<pycaret.internal.Display.Display object at 0x000001CFB6416DF0>, kwargs={})
2022-02-13 01:27:17,098:INFO:Checking exceptions
2022-02-13 01:27:17,098:INFO:Importing libraries
2022-02-13 01:27:17,098:INFO:Copying training dataset
2022-02-13 01:27:17,100:INFO:Defining folds
2022-02-13 01:27:17,100:INFO:Declaring metric variables
2022-02-13 01:27:17,109:INFO:Importing untrained model
2022-02-13 01:27:17,118:INFO:Light Gradient Boosting Machine Imported succesfully
2022-02-13 01:27:17,137:INFO:Starting cross validation
2022-02-13 01:27:17,138:INFO:Cross validating with StratifiedKFold(n_splits=10, random_state=None, shuffle=False), n_jobs=-1
2022-02-13 01:27:17,139:ERROR:create_model() for lightgbm raised an exception or returned all 0.0:
2022-02-13 01:27:17,143:ERROR:Traceback (most recent call last):
  File "C:\Users\TP\anaconda3\lib\site-packages\joblib\parallel.py", line 827, in dispatch_one_batch
    tasks = self._ready_batches.get(block=False)
  File "C:\Users\TP\anaconda3\lib\queue.py", line 167, in get
    raise Empty
_queue.Empty

During handling of the above exception, another exception occurred:

Traceback (most recent call last):
  File "C:\Users\TP\AppData\Roaming\Python\Python38\site-packages\pycaret\internal\tabular.py", line 2206, in compare_models
    model, model_fit_time = create_model_supervised(**create_model_args)
  File "C:\Users\TP\AppData\Roaming\Python\Python38\site-packages\pycaret\internal\tabular.py", line 3171, in create_model_supervised
    scores = cross_validate(
  File "C:\Users\TP\anaconda3\lib\site-packages\sklearn\utils\validation.py", line 72, in inner_f
    return f(**kwargs)
  File "C:\Users\TP\anaconda3\lib\site-packages\sklearn\model_selection\_validation.py", line 242, in cross_validate
    scores = parallel(
  File "C:\Users\TP\anaconda3\lib\site-packages\joblib\parallel.py", line 1048, in __call__
    if self.dispatch_one_batch(iterator):
  File "C:\Users\TP\anaconda3\lib\site-packages\joblib\parallel.py", line 838, in dispatch_one_batch
    islice = list(itertools.islice(iterator, big_batch_size))
  File "C:\Users\TP\anaconda3\lib\site-packages\sklearn\model_selection\_validation.py", line 242, in <genexpr>
    scores = parallel(
  File "C:\Users\TP\anaconda3\lib\site-packages\sklearn\model_selection\_split.py", line 336, in split
    for train, test in super().split(X, y, groups):
  File "C:\Users\TP\anaconda3\lib\site-packages\sklearn\model_selection\_split.py", line 80, in split
    for test_index in self._iter_test_masks(X, y, groups):
  File "C:\Users\TP\anaconda3\lib\site-packages\sklearn\model_selection\_split.py", line 697, in _iter_test_masks
    test_folds = self._make_test_folds(X, y)
  File "C:\Users\TP\anaconda3\lib\site-packages\sklearn\model_selection\_split.py", line 649, in _make_test_folds
    raise ValueError(
ValueError: Supported target types are: ('binary', 'multiclass'). Got 'continuous' instead.

During handling of the above exception, another exception occurred:

Traceback (most recent call last):
  File "C:\Users\TP\anaconda3\lib\site-packages\joblib\parallel.py", line 827, in dispatch_one_batch
    tasks = self._ready_batches.get(block=False)
  File "C:\Users\TP\anaconda3\lib\queue.py", line 167, in get
    raise Empty
_queue.Empty

During handling of the above exception, another exception occurred:

Traceback (most recent call last):
  File "C:\Users\TP\AppData\Roaming\Python\Python38\site-packages\pycaret\internal\tabular.py", line 2215, in compare_models
    model, model_fit_time = create_model_supervised(**create_model_args)
  File "C:\Users\TP\AppData\Roaming\Python\Python38\site-packages\pycaret\internal\tabular.py", line 3171, in create_model_supervised
    scores = cross_validate(
  File "C:\Users\TP\anaconda3\lib\site-packages\sklearn\utils\validation.py", line 72, in inner_f
    return f(**kwargs)
  File "C:\Users\TP\anaconda3\lib\site-packages\sklearn\model_selection\_validation.py", line 242, in cross_validate
    scores = parallel(
  File "C:\Users\TP\anaconda3\lib\site-packages\joblib\parallel.py", line 1048, in __call__
    if self.dispatch_one_batch(iterator):
  File "C:\Users\TP\anaconda3\lib\site-packages\joblib\parallel.py", line 838, in dispatch_one_batch
    islice = list(itertools.islice(iterator, big_batch_size))
  File "C:\Users\TP\anaconda3\lib\site-packages\sklearn\model_selection\_validation.py", line 242, in <genexpr>
    scores = parallel(
  File "C:\Users\TP\anaconda3\lib\site-packages\sklearn\model_selection\_split.py", line 336, in split
    for train, test in super().split(X, y, groups):
  File "C:\Users\TP\anaconda3\lib\site-packages\sklearn\model_selection\_split.py", line 80, in split
    for test_index in self._iter_test_masks(X, y, groups):
  File "C:\Users\TP\anaconda3\lib\site-packages\sklearn\model_selection\_split.py", line 697, in _iter_test_masks
    test_folds = self._make_test_folds(X, y)
  File "C:\Users\TP\anaconda3\lib\site-packages\sklearn\model_selection\_split.py", line 649, in _make_test_folds
    raise ValueError(
ValueError: Supported target types are: ('binary', 'multiclass'). Got 'continuous' instead.

2022-02-13 01:27:17,143:INFO:Initializing CatBoost Classifier
2022-02-13 01:27:17,144:INFO:Total runtime is 0.03068203131357829 minutes
2022-02-13 01:27:17,153:INFO:SubProcess create_model() called ==================================
2022-02-13 01:27:17,153:INFO:Initializing create_model()
2022-02-13 01:27:17,153:INFO:create_model(estimator=catboost, fold=StratifiedKFold(n_splits=10, random_state=None, shuffle=False), round=4, cross_validation=True, predict=True, fit_kwargs={}, groups=None, refit=False, verbose=False, system=False, metrics=None, add_to_model_list=True, probability_threshold=None, display=<pycaret.internal.Display.Display object at 0x000001CFB6416DF0>, kwargs={})
2022-02-13 01:27:17,153:INFO:Checking exceptions
2022-02-13 01:27:17,153:INFO:Importing libraries
2022-02-13 01:27:17,154:INFO:Copying training dataset
2022-02-13 01:27:17,156:INFO:Defining folds
2022-02-13 01:27:17,156:INFO:Declaring metric variables
2022-02-13 01:27:17,165:INFO:Importing untrained model
2022-02-13 01:27:17,174:INFO:CatBoost Classifier Imported succesfully
2022-02-13 01:27:17,193:INFO:Starting cross validation
2022-02-13 01:27:17,208:INFO:Cross validating with StratifiedKFold(n_splits=10, random_state=None, shuffle=False), n_jobs=-1
2022-02-13 01:27:17,210:WARNING:create_model() for catboost raised an exception or returned all 0.0, trying without fit_kwargs:
2022-02-13 01:27:17,211:WARNING:Traceback (most recent call last):
  File "C:\Users\TP\anaconda3\lib\site-packages\joblib\parallel.py", line 827, in dispatch_one_batch
    tasks = self._ready_batches.get(block=False)
  File "C:\Users\TP\anaconda3\lib\queue.py", line 167, in get
    raise Empty
_queue.Empty

During handling of the above exception, another exception occurred:

Traceback (most recent call last):
  File "C:\Users\TP\AppData\Roaming\Python\Python38\site-packages\pycaret\internal\tabular.py", line 2206, in compare_models
    model, model_fit_time = create_model_supervised(**create_model_args)
  File "C:\Users\TP\AppData\Roaming\Python\Python38\site-packages\pycaret\internal\tabular.py", line 3171, in create_model_supervised
    scores = cross_validate(
  File "C:\Users\TP\anaconda3\lib\site-packages\sklearn\utils\validation.py", line 72, in inner_f
    return f(**kwargs)
  File "C:\Users\TP\anaconda3\lib\site-packages\sklearn\model_selection\_validation.py", line 242, in cross_validate
    scores = parallel(
  File "C:\Users\TP\anaconda3\lib\site-packages\joblib\parallel.py", line 1048, in __call__
    if self.dispatch_one_batch(iterator):
  File "C:\Users\TP\anaconda3\lib\site-packages\joblib\parallel.py", line 838, in dispatch_one_batch
    islice = list(itertools.islice(iterator, big_batch_size))
  File "C:\Users\TP\anaconda3\lib\site-packages\sklearn\model_selection\_validation.py", line 242, in <genexpr>
    scores = parallel(
  File "C:\Users\TP\anaconda3\lib\site-packages\sklearn\model_selection\_split.py", line 336, in split
    for train, test in super().split(X, y, groups):
  File "C:\Users\TP\anaconda3\lib\site-packages\sklearn\model_selection\_split.py", line 80, in split
    for test_index in self._iter_test_masks(X, y, groups):
  File "C:\Users\TP\anaconda3\lib\site-packages\sklearn\model_selection\_split.py", line 697, in _iter_test_masks
    test_folds = self._make_test_folds(X, y)
  File "C:\Users\TP\anaconda3\lib\site-packages\sklearn\model_selection\_split.py", line 649, in _make_test_folds
    raise ValueError(
ValueError: Supported target types are: ('binary', 'multiclass'). Got 'continuous' instead.

2022-02-13 01:27:17,211:INFO:Initializing create_model()
2022-02-13 01:27:17,211:INFO:create_model(estimator=catboost, fold=StratifiedKFold(n_splits=10, random_state=None, shuffle=False), round=4, cross_validation=True, predict=True, fit_kwargs={}, groups=None, refit=False, verbose=False, system=False, metrics=None, add_to_model_list=True, probability_threshold=None, display=<pycaret.internal.Display.Display object at 0x000001CFB6416DF0>, kwargs={})
2022-02-13 01:27:17,211:INFO:Checking exceptions
2022-02-13 01:27:17,211:INFO:Importing libraries
2022-02-13 01:27:17,211:INFO:Copying training dataset
2022-02-13 01:27:17,214:INFO:Defining folds
2022-02-13 01:27:17,214:INFO:Declaring metric variables
2022-02-13 01:27:17,222:INFO:Importing untrained model
2022-02-13 01:27:17,229:INFO:CatBoost Classifier Imported succesfully
2022-02-13 01:27:17,247:INFO:Starting cross validation
2022-02-13 01:27:17,247:INFO:Cross validating with StratifiedKFold(n_splits=10, random_state=None, shuffle=False), n_jobs=-1
2022-02-13 01:27:17,250:ERROR:create_model() for catboost raised an exception or returned all 0.0:
2022-02-13 01:27:17,253:ERROR:Traceback (most recent call last):
  File "C:\Users\TP\anaconda3\lib\site-packages\joblib\parallel.py", line 827, in dispatch_one_batch
    tasks = self._ready_batches.get(block=False)
  File "C:\Users\TP\anaconda3\lib\queue.py", line 167, in get
    raise Empty
_queue.Empty

During handling of the above exception, another exception occurred:

Traceback (most recent call last):
  File "C:\Users\TP\AppData\Roaming\Python\Python38\site-packages\pycaret\internal\tabular.py", line 2206, in compare_models
    model, model_fit_time = create_model_supervised(**create_model_args)
  File "C:\Users\TP\AppData\Roaming\Python\Python38\site-packages\pycaret\internal\tabular.py", line 3171, in create_model_supervised
    scores = cross_validate(
  File "C:\Users\TP\anaconda3\lib\site-packages\sklearn\utils\validation.py", line 72, in inner_f
    return f(**kwargs)
  File "C:\Users\TP\anaconda3\lib\site-packages\sklearn\model_selection\_validation.py", line 242, in cross_validate
    scores = parallel(
  File "C:\Users\TP\anaconda3\lib\site-packages\joblib\parallel.py", line 1048, in __call__
    if self.dispatch_one_batch(iterator):
  File "C:\Users\TP\anaconda3\lib\site-packages\joblib\parallel.py", line 838, in dispatch_one_batch
    islice = list(itertools.islice(iterator, big_batch_size))
  File "C:\Users\TP\anaconda3\lib\site-packages\sklearn\model_selection\_validation.py", line 242, in <genexpr>
    scores = parallel(
  File "C:\Users\TP\anaconda3\lib\site-packages\sklearn\model_selection\_split.py", line 336, in split
    for train, test in super().split(X, y, groups):
  File "C:\Users\TP\anaconda3\lib\site-packages\sklearn\model_selection\_split.py", line 80, in split
    for test_index in self._iter_test_masks(X, y, groups):
  File "C:\Users\TP\anaconda3\lib\site-packages\sklearn\model_selection\_split.py", line 697, in _iter_test_masks
    test_folds = self._make_test_folds(X, y)
  File "C:\Users\TP\anaconda3\lib\site-packages\sklearn\model_selection\_split.py", line 649, in _make_test_folds
    raise ValueError(
ValueError: Supported target types are: ('binary', 'multiclass'). Got 'continuous' instead.

During handling of the above exception, another exception occurred:

Traceback (most recent call last):
  File "C:\Users\TP\anaconda3\lib\site-packages\joblib\parallel.py", line 827, in dispatch_one_batch
    tasks = self._ready_batches.get(block=False)
  File "C:\Users\TP\anaconda3\lib\queue.py", line 167, in get
    raise Empty
_queue.Empty

During handling of the above exception, another exception occurred:

Traceback (most recent call last):
  File "C:\Users\TP\AppData\Roaming\Python\Python38\site-packages\pycaret\internal\tabular.py", line 2215, in compare_models
    model, model_fit_time = create_model_supervised(**create_model_args)
  File "C:\Users\TP\AppData\Roaming\Python\Python38\site-packages\pycaret\internal\tabular.py", line 3171, in create_model_supervised
    scores = cross_validate(
  File "C:\Users\TP\anaconda3\lib\site-packages\sklearn\utils\validation.py", line 72, in inner_f
    return f(**kwargs)
  File "C:\Users\TP\anaconda3\lib\site-packages\sklearn\model_selection\_validation.py", line 242, in cross_validate
    scores = parallel(
  File "C:\Users\TP\anaconda3\lib\site-packages\joblib\parallel.py", line 1048, in __call__
    if self.dispatch_one_batch(iterator):
  File "C:\Users\TP\anaconda3\lib\site-packages\joblib\parallel.py", line 838, in dispatch_one_batch
    islice = list(itertools.islice(iterator, big_batch_size))
  File "C:\Users\TP\anaconda3\lib\site-packages\sklearn\model_selection\_validation.py", line 242, in <genexpr>
    scores = parallel(
  File "C:\Users\TP\anaconda3\lib\site-packages\sklearn\model_selection\_split.py", line 336, in split
    for train, test in super().split(X, y, groups):
  File "C:\Users\TP\anaconda3\lib\site-packages\sklearn\model_selection\_split.py", line 80, in split
    for test_index in self._iter_test_masks(X, y, groups):
  File "C:\Users\TP\anaconda3\lib\site-packages\sklearn\model_selection\_split.py", line 697, in _iter_test_masks
    test_folds = self._make_test_folds(X, y)
  File "C:\Users\TP\anaconda3\lib\site-packages\sklearn\model_selection\_split.py", line 649, in _make_test_folds
    raise ValueError(
ValueError: Supported target types are: ('binary', 'multiclass'). Got 'continuous' instead.

2022-02-13 01:27:17,253:INFO:Initializing Dummy Classifier
2022-02-13 01:27:17,254:INFO:Total runtime is 0.032514504591623944 minutes
2022-02-13 01:27:17,262:INFO:SubProcess create_model() called ==================================
2022-02-13 01:27:17,263:INFO:Initializing create_model()
2022-02-13 01:27:17,263:INFO:create_model(estimator=dummy, fold=StratifiedKFold(n_splits=10, random_state=None, shuffle=False), round=4, cross_validation=True, predict=True, fit_kwargs={}, groups=None, refit=False, verbose=False, system=False, metrics=None, add_to_model_list=True, probability_threshold=None, display=<pycaret.internal.Display.Display object at 0x000001CFB6416DF0>, kwargs={})
2022-02-13 01:27:17,263:INFO:Checking exceptions
2022-02-13 01:27:17,263:INFO:Importing libraries
2022-02-13 01:27:17,263:INFO:Copying training dataset
2022-02-13 01:27:17,266:INFO:Defining folds
2022-02-13 01:27:17,266:INFO:Declaring metric variables
2022-02-13 01:27:17,274:INFO:Importing untrained model
2022-02-13 01:27:17,284:INFO:Dummy Classifier Imported succesfully
2022-02-13 01:27:17,302:INFO:Starting cross validation
2022-02-13 01:27:17,303:INFO:Cross validating with StratifiedKFold(n_splits=10, random_state=None, shuffle=False), n_jobs=-1
2022-02-13 01:27:17,305:WARNING:create_model() for dummy raised an exception or returned all 0.0, trying without fit_kwargs:
2022-02-13 01:27:17,307:WARNING:Traceback (most recent call last):
  File "C:\Users\TP\anaconda3\lib\site-packages\joblib\parallel.py", line 827, in dispatch_one_batch
    tasks = self._ready_batches.get(block=False)
  File "C:\Users\TP\anaconda3\lib\queue.py", line 167, in get
    raise Empty
_queue.Empty

During handling of the above exception, another exception occurred:

Traceback (most recent call last):
  File "C:\Users\TP\AppData\Roaming\Python\Python38\site-packages\pycaret\internal\tabular.py", line 2206, in compare_models
    model, model_fit_time = create_model_supervised(**create_model_args)
  File "C:\Users\TP\AppData\Roaming\Python\Python38\site-packages\pycaret\internal\tabular.py", line 3171, in create_model_supervised
    scores = cross_validate(
  File "C:\Users\TP\anaconda3\lib\site-packages\sklearn\utils\validation.py", line 72, in inner_f
    return f(**kwargs)
  File "C:\Users\TP\anaconda3\lib\site-packages\sklearn\model_selection\_validation.py", line 242, in cross_validate
    scores = parallel(
  File "C:\Users\TP\anaconda3\lib\site-packages\joblib\parallel.py", line 1048, in __call__
    if self.dispatch_one_batch(iterator):
  File "C:\Users\TP\anaconda3\lib\site-packages\joblib\parallel.py", line 838, in dispatch_one_batch
    islice = list(itertools.islice(iterator, big_batch_size))
  File "C:\Users\TP\anaconda3\lib\site-packages\sklearn\model_selection\_validation.py", line 242, in <genexpr>
    scores = parallel(
  File "C:\Users\TP\anaconda3\lib\site-packages\sklearn\model_selection\_split.py", line 336, in split
    for train, test in super().split(X, y, groups):
  File "C:\Users\TP\anaconda3\lib\site-packages\sklearn\model_selection\_split.py", line 80, in split
    for test_index in self._iter_test_masks(X, y, groups):
  File "C:\Users\TP\anaconda3\lib\site-packages\sklearn\model_selection\_split.py", line 697, in _iter_test_masks
    test_folds = self._make_test_folds(X, y)
  File "C:\Users\TP\anaconda3\lib\site-packages\sklearn\model_selection\_split.py", line 649, in _make_test_folds
    raise ValueError(
ValueError: Supported target types are: ('binary', 'multiclass'). Got 'continuous' instead.

2022-02-13 01:27:17,307:INFO:Initializing create_model()
2022-02-13 01:27:17,307:INFO:create_model(estimator=dummy, fold=StratifiedKFold(n_splits=10, random_state=None, shuffle=False), round=4, cross_validation=True, predict=True, fit_kwargs={}, groups=None, refit=False, verbose=False, system=False, metrics=None, add_to_model_list=True, probability_threshold=None, display=<pycaret.internal.Display.Display object at 0x000001CFB6416DF0>, kwargs={})
2022-02-13 01:27:17,307:INFO:Checking exceptions
2022-02-13 01:27:17,307:INFO:Importing libraries
2022-02-13 01:27:17,308:INFO:Copying training dataset
2022-02-13 01:27:17,310:INFO:Defining folds
2022-02-13 01:27:17,310:INFO:Declaring metric variables
2022-02-13 01:27:17,318:INFO:Importing untrained model
2022-02-13 01:27:17,327:INFO:Dummy Classifier Imported succesfully
2022-02-13 01:27:17,345:INFO:Starting cross validation
2022-02-13 01:27:17,346:INFO:Cross validating with StratifiedKFold(n_splits=10, random_state=None, shuffle=False), n_jobs=-1
2022-02-13 01:27:17,348:ERROR:create_model() for dummy raised an exception or returned all 0.0:
2022-02-13 01:27:17,351:ERROR:Traceback (most recent call last):
  File "C:\Users\TP\anaconda3\lib\site-packages\joblib\parallel.py", line 827, in dispatch_one_batch
    tasks = self._ready_batches.get(block=False)
  File "C:\Users\TP\anaconda3\lib\queue.py", line 167, in get
    raise Empty
_queue.Empty

During handling of the above exception, another exception occurred:

Traceback (most recent call last):
  File "C:\Users\TP\AppData\Roaming\Python\Python38\site-packages\pycaret\internal\tabular.py", line 2206, in compare_models
    model, model_fit_time = create_model_supervised(**create_model_args)
  File "C:\Users\TP\AppData\Roaming\Python\Python38\site-packages\pycaret\internal\tabular.py", line 3171, in create_model_supervised
    scores = cross_validate(
  File "C:\Users\TP\anaconda3\lib\site-packages\sklearn\utils\validation.py", line 72, in inner_f
    return f(**kwargs)
  File "C:\Users\TP\anaconda3\lib\site-packages\sklearn\model_selection\_validation.py", line 242, in cross_validate
    scores = parallel(
  File "C:\Users\TP\anaconda3\lib\site-packages\joblib\parallel.py", line 1048, in __call__
    if self.dispatch_one_batch(iterator):
  File "C:\Users\TP\anaconda3\lib\site-packages\joblib\parallel.py", line 838, in dispatch_one_batch
    islice = list(itertools.islice(iterator, big_batch_size))
  File "C:\Users\TP\anaconda3\lib\site-packages\sklearn\model_selection\_validation.py", line 242, in <genexpr>
    scores = parallel(
  File "C:\Users\TP\anaconda3\lib\site-packages\sklearn\model_selection\_split.py", line 336, in split
    for train, test in super().split(X, y, groups):
  File "C:\Users\TP\anaconda3\lib\site-packages\sklearn\model_selection\_split.py", line 80, in split
    for test_index in self._iter_test_masks(X, y, groups):
  File "C:\Users\TP\anaconda3\lib\site-packages\sklearn\model_selection\_split.py", line 697, in _iter_test_masks
    test_folds = self._make_test_folds(X, y)
  File "C:\Users\TP\anaconda3\lib\site-packages\sklearn\model_selection\_split.py", line 649, in _make_test_folds
    raise ValueError(
ValueError: Supported target types are: ('binary', 'multiclass'). Got 'continuous' instead.

During handling of the above exception, another exception occurred:

Traceback (most recent call last):
  File "C:\Users\TP\anaconda3\lib\site-packages\joblib\parallel.py", line 827, in dispatch_one_batch
    tasks = self._ready_batches.get(block=False)
  File "C:\Users\TP\anaconda3\lib\queue.py", line 167, in get
    raise Empty
_queue.Empty

During handling of the above exception, another exception occurred:

Traceback (most recent call last):
  File "C:\Users\TP\AppData\Roaming\Python\Python38\site-packages\pycaret\internal\tabular.py", line 2215, in compare_models
    model, model_fit_time = create_model_supervised(**create_model_args)
  File "C:\Users\TP\AppData\Roaming\Python\Python38\site-packages\pycaret\internal\tabular.py", line 3171, in create_model_supervised
    scores = cross_validate(
  File "C:\Users\TP\anaconda3\lib\site-packages\sklearn\utils\validation.py", line 72, in inner_f
    return f(**kwargs)
  File "C:\Users\TP\anaconda3\lib\site-packages\sklearn\model_selection\_validation.py", line 242, in cross_validate
    scores = parallel(
  File "C:\Users\TP\anaconda3\lib\site-packages\joblib\parallel.py", line 1048, in __call__
    if self.dispatch_one_batch(iterator):
  File "C:\Users\TP\anaconda3\lib\site-packages\joblib\parallel.py", line 838, in dispatch_one_batch
    islice = list(itertools.islice(iterator, big_batch_size))
  File "C:\Users\TP\anaconda3\lib\site-packages\sklearn\model_selection\_validation.py", line 242, in <genexpr>
    scores = parallel(
  File "C:\Users\TP\anaconda3\lib\site-packages\sklearn\model_selection\_split.py", line 336, in split
    for train, test in super().split(X, y, groups):
  File "C:\Users\TP\anaconda3\lib\site-packages\sklearn\model_selection\_split.py", line 80, in split
    for test_index in self._iter_test_masks(X, y, groups):
  File "C:\Users\TP\anaconda3\lib\site-packages\sklearn\model_selection\_split.py", line 697, in _iter_test_masks
    test_folds = self._make_test_folds(X, y)
  File "C:\Users\TP\anaconda3\lib\site-packages\sklearn\model_selection\_split.py", line 649, in _make_test_folds
    raise ValueError(
ValueError: Supported target types are: ('binary', 'multiclass'). Got 'continuous' instead.

2022-02-13 01:27:17,367:INFO:create_model_container: 0
2022-02-13 01:27:17,367:INFO:master_model_container: 0
2022-02-13 01:27:17,368:INFO:display_container: 2
2022-02-13 01:27:17,368:INFO:[]
2022-02-13 01:27:17,368:INFO:compare_models() succesfully completed......................................
2022-02-13 01:27:17,368:INFO:Initializing automl()
2022-02-13 01:27:17,368:INFO:automl(optimize=Accuracy, use_holdout=False)
2022-02-13 01:27:17,369:INFO:Model Selection Basis : CV Results on Training set
